Workbook

Sheet Exec Summary
A1: Space Exploration Technologies Corp. (SpaceX) | $SPCX | Pre-IPO Valuation Executive Summary
A2: ="Prepared: "&TEXT(TODAY(),"d-mmm-yyyy")&" | Source: SpaceX S-1 (Filed 20-May-2026) " -> Prepared: 11-Jun-2026 | Source: SpaceX S-1 (Filed 20-May-2026)
A4: INVESTMENT THESIS
A6: SpaceX is pursuing an IPO at $135/share, implying a fully diluted market cap of ~$1.75T. The company operates three segments:
A7: (1) Connectivity (Starlink) — satellite broadband, ~60% of FY2025 revenue, highest margin segment growing 50%+ YoY
A8: (2) Space (Launch + Starship) — launch services and government contracts, ~22% of revenue, steady growth anchored by Falcon 9 cadence
A9: (3) AI (X / xAI / Grok) — social media and AI compute infrastructure, ~17% of revenue, pre-profit but scaling rapidly
A11: Our 3-segment SOTP DCF analysis uses 20-year explicit forecasts per segment with comp-driven WACCs and terminal values.
A12: Two methodologies are applied: (1) Gordon Growth / EV-Revenue and (2) Exit Multiple / Gordon cross-check.
A14: VALUATION CONCLUSION
B15: Method 1 ¹ | C15: Method 2 ² | D15: Average | F15: Notes
A16: Total Enterprise Value ($M) | B16: =SOTP!B11 -> 647687.64 | C16: =SOTP!C11 -> 501724.74 | D16: =SOTP!D11 -> 574706.19 | F16: ¹ Gordon Growth (Conn/Space) + EV/Revenue (AI)
A17: Equity Value ($M) | B17: =SOTP!B20 -> 649148.64 | C17: =SOTP!C20 -> 503185.74 | D17: =SOTP!D20 -> 576167.19 | F17: ² Exit Multiple (Conn/Space) + Gordon (AI cross-check)
A18: Implied Price / Share (fully diluted) | B18: =B17/SOTP!B25 -> 50.08863 | C18: =C17/SOTP!C25 -> 38.82606 | D18: =D17/SOTP!D25 -> 44.457345 | F18: Fully diluted: 12,960M shares (preferred conversion + xAI merger + RSUs + IPO)
A19: IPO Reference Price | B19: =COVER!B5 -> 135 | C19: =B19 -> 135 | D19: =B19 -> 135
A20: Upside / (Downside) to IPO | B20: =B18/B19-1 -> -0.62897311 | C20: =C18/C19-1 -> -0.71239956 | D20: =D18/D19-1 -> -0.67068634
A21: Shares Outstanding — Fully Diluted (M) | B21: =SOTP!B25 -> 12960
A23: SEGMENT VALUATION BREAKDOWN
A25: Segment | B25: Avg EV ($M) | C25: % of SOTP | D25: WACC | E25: Tg | F25: Primary Methodology
A26: Connectivity (Starlink) | B26: =SOTP!D8 -> 436046.2 | C26: =SOTP!E8 -> 0.7587289 | D26: =WACC!B47 -> 0.075445353 | E26: =WACC!C47 -> 0.03 | F26: Gordon Growth perpetuity + EV/EBITDA exit cross-check
A27: Space (Launch + Starship) | B27: =SOTP!D9 -> 91383.931 | C27: =SOTP!E9 -> 0.15900983 | D27: =WACC!B48 -> 0.079328832 | E27: =WACC!C48 -> 0.025 | F27: Gordon Growth perpetuity + EV/EBITDA exit cross-check
A28: AI (X / xAI / Grok) | B28: =SOTP!D10 -> 47276.062 | C28: =SOTP!E10 -> 0.082261271 | D28: =WACC!B49 -> 0.11585358 | E28: =WACC!C49 -> 0.035 | F28: EV/Revenue multiple (primary) — Gordon distorts on loss-making FCF
A29: Total SOTP | B29: =SOTP!D11 -> 574706.19 | C29: =SOTP!E11 -> 1
A31: KEY ASSUMPTIONS (Base Case)
A33: Item | B33: Connectivity | C33: Space | D33: AI | F33: Source
A34: Forecast Horizon | B34: 20 years | C34: 20 years | D34: 20 years | F34: DCF sheet assumptions
A35: WACC | B35: =WACC!B47 -> 0.075445353 | C35: =WACC!B48 -> 0.079328832 | D35: =WACC!B49 -> 0.11585358 | F35: Comp-driven; WACC sheet
A36: Terminal Growth Rate | B36: =WACC!C47 -> 0.03 | C36: =WACC!C48 -> 0.025 | D36: =WACC!C49 -> 0.035 | F36: WACC sheet
A37: Risk-Free Rate | B37: =WACC!B6 -> 0.0435 | F37: 10Y UST, Jun 2026
A38: Equity Risk Premium | B38: =WACC!B7 -> 0.055 | F38: Damodaran implied ERP, Jan 2026
A39: Tax Rate | B39: =WACC!B8 -> 0.21 | F39: US statutory; large NOL carryforwards
A41: FY2025 ACTUALS (S-1 Source)
A43: Metric | B43: FY2025 | C43: YoY | F43: Note
A44: Total Revenue ($M) | B44: =SOTP!D38 -> 18674 | C44: =SOTP!D38/SOTP!C38-1 -> 0.33242954 | F44: Consolidated — 3 segments
A45: Connectivity | B45: =SOTP!D39 -> 11387 | C45: =SOTP!D39/SOTP!C39-1 -> 0.49848664 | F45: 60.9% of total; 63% EBITDA margin
A46: Space | B46: =SOTP!D40 -> 4086 | C46: =SOTP!D40/SOTP!C40-1 -> 0.076396207 | F46: 21.9% of total; Falcon 9 cadence + Starship
A47: AI | B47: =SOTP!D41 -> 3201 | C47: =SOTP!D41/SOTP!C41-1 -> 0.22175573 | F47: 17.1% of total; X ads + xAI compute
A48: Net Income ($M) | B48: =SOTP!D44 -> -4937 | F48: AI segment losses dominate; R&D $8.6B
A49: Operating Cash Flow ($M) | B49: =SOTP!D43 -> 6785 | F49: Cash-generative despite heavy capex cycle
A50: Total Capex ($M) | B50: =SOTP!D42 -> -20737 | F50: AI infra $12.7B = 61% of total capex
...

Sheet COVER
A1: Space Exploration Technologies Corp. (SpaceX) | $SPCX | Sum-of-the-Parts DCF Valuation
A2: 3-Segment SOTP (Connectivity + Space + AI) | 10-Year Explicit DCF | S-1 Filed May 20, 2026 | $ in Millions (except per share)
A4: ① ENTER PRICE TO SEE UPSIDE / DOWNSIDE
A5: Current / IPO Share Price ($) | B5: 135 | C5: ← Enter the IPO / current trading price here
A7: ② VALUATION SUMMARY (Base Case)
B8: Gordon Growth | C8: Exit Multiple | D8: Average | H8: Note
A9: Total SOTP Enterprise Value ($M) | B9: =SOTP!B11 -> 647687.64 | C9: =SOTP!C11 -> 501724.74 | D9: =SOTP!D11 -> 574706.19
A10: (+) Net Cash (Cash − Total Debt) ($M) | B10: =SOTP!B16+SOTP!B17 -> 1461 | C10: =SOTP!C16+SOTP!C17 -> 1461 | D10: =SOTP!D16+SOTP!D17 -> 1461
A11: Connectivity Segment EV ($M) | B11: =SOTP!B8 -> 524537.59 | C11: =SOTP!C8 -> 347554.8 | D11: =SOTP!D8 -> 436046.2 | H11: 83% of avg SOTP EV
A12: Space Segment EV ($M) | B12: =SOTP!B9 -> 85853.059 | C12: =SOTP!C9 -> 96914.802 | D12: =SOTP!D9 -> 91383.931 | H12: 9% of avg SOTP EV
A13: AI Segment EV ($M) | B13: =SOTP!B10 -> 37296.99 | C13: =SOTP!C10 -> 57255.133 | D13: =SOTP!D10 -> 47276.062 | H13: 8% of avg SOTP EV — wide range
A14: Equity Value ($M) | B14: =SOTP!B20 -> 649148.64 | C14: =SOTP!C20 -> 503185.74 | D14: =SOTP!D20 -> 576167.19 | H14: After debt, cash, pref conversion
A16: Implied Share Price | B16: Gordon Growth | C16: Exit Multiple | D16: Average | H16: Shares Basis
A17: Basic — Common only (5,798M) | B17: =SOTP!B26 -> 111.96079 | C17: =SOTP!C26 -> 86.786088 | D17: =SOTP!D26 -> 99.373437 | H17: Understates: excludes converted pref + xAI shares
A18: Fully Diluted, Post-IPO (12,960M) | B18: =SOTP!B27 -> 50.08863 | C18: =SOTP!C27 -> 38.82606 | D18: =SOTP!D27 -> 44.457345 | H18: ★ Reconciled to actual $135 IPO / $1.75T — primary metric
A20: ③ UPSIDE / (DOWNSIDE) vs. ENTERED PRICE (Fully-Diluted shares — primary)
B21: Gordon Growth | C21: Exit Multiple | D21: Average
A22: Our Implied Price (Fully-Diluted) | B22: =B18 -> 50.08863 | C22: =C18 -> 38.82606 | D22: =D18 -> 44.457345
A23: Current / IPO Price | B23: =IF(B5="","—",B5) -> 135 | C23: =IF(B5="","—",B5) -> 135 | D23: =IF(B5="","—",B5) -> 135
A24: Implied Upside / (Downside) | B24: =IF(B5="","← Enter price",(B18/B5)-1) -> -0.62897311 | C24: =IF(B5="","← Enter price",(C18/B5)-1) -> -0.71239956 | D24: =IF(B5="","← Enter price",(D18/B5)-1) -> -0.67068634
A26: ④ SCENARIO SELECTORS (1=Bear, 2=Base, 3=Bull — changes all 3 segment DCFs simultaneously)
A27: Segment | B27: Scenario (1/2/3) | C27: Selected | D27: WACC | E27: Terminal Growth (Base)
A28: Connectivity (Starlink) | B28: 2 | C28: =IF(B28=1,"◀ BEAR",IF(B28=2,"◀ BASE","◀ BULL")) -> ◀ BASE | D28: =WACC!B43 -> 0.075445353 | E28: =WACC!C47 -> 0.03
A29: Space (Launch + Starship) | B29: 2 | C29: =IF(B29=1,"◀ BEAR",IF(B29=2,"◀ BASE","◀ BULL")) -> ◀ BASE | D29: =WACC!C43 -> 0.079328832 | E29: =WACC!C48 -> 0.025
A30: AI (X / xAI / Grok) | B30: 2 | C30: =IF(B30=1,"◀ BEAR",IF(B30=2,"◀ BASE","◀ BULL")) -> ◀ BASE | D30: =WACC!D43 -> 0.11585358 | E30: =WACC!C49 -> 0.035
A31: ✓ Set scenarios here (B28:B30). 1=Bear, 2=Base, 3=Bull. Segment tabs follow automatically — whole valuation controlled from this page.
A33: ⑤ VALUATION SUMMARY (Implied Price/Share, Basic | Selected Scenario)
A34: Method | B34: Per Share (Basic) | H34: Note
A35: Gordon Growth (Perpetuity) | B35: =SOTP!B26 -> 111.96079 | C35: =SOTP!B26 -> 111.96079 | D35: =SOTP!B26 -> 111.96079 | H35: Changes with Scenario Selector (B28:B30 above)
A36: Exit Multiple | B36: =SOTP!C26 -> 86.786088 | C36: =SOTP!C26 -> 86.786088 | D36: =SOTP!C26 -> 86.786088
A37: Average (Gordon & Exit) | B37: =SOTP!D26 -> 99.373437 | C37: =SOTP!D26 -> 99.373437 | D37: =SOTP!D26 -> 99.373437
A39: ⑥ SENSITIVITY: Implied Price/Share (Fully-Diluted) — Connectivity WACC vs. Terminal Growth Rate (Base Case)
A40: WACC \ Term. Growth | B40: =SOTP!C51 -> 0.02 | C40: =SOTP!D51 -> 0.025 | D40: =SOTP!E51 -> 0.03 | E40: =SOTP!F51 -> 0.035 | F40: =SOTP!G51 -> 0.04
A41: =SOTP!B52 -> 0.055445353 | B41: =SOTP!C52 -> 72.539151 | C41: =SOTP!D52 -> 79.266728 | D41: =SOTP!E52 -> 88.638238 | E41: =SOTP!F52 -> 102.59343 | F41: =SOTP!G52 -> 125.58384
A42: =SOTP!B53 -> 0.065445353 | B42: =SOTP!C53 -> 56.245372 | C42: =SOTP!D53 -> 59.562907 | D42: =SOTP!E53 -> 63.816399 | E42: =SOTP!F53 -> 69.466983 | F42: =SOTP!G53 -> 77.33824
A43: =SOTP!B54 -> 0.075445353 | B43: =SOTP!C54 -> 46.016783 | C43: =SOTP!D54 -> 47.850912 | D43: =SOTP!E54 -> 50.08863 | E43: =SOTP!F54 -> 52.879617 | F43: =SOTP!G54 -> 56.458011
A44: =SOTP!B55 -> 0.085445353 | B44: =SOTP!C55 -> 39.0546 | C44: =SOTP!D55 -> 40.147326 | D44: =SOTP!E55 -> 41.437134 | E44: =SOTP!F55 -> 42.982626 | F44: =SOTP!G55 -> 44.868195
A45: =SOTP!B56 -> 0.095445353 | B45: =SOTP!C56 -> 34.046068 | C45: =SOTP!D56 -> 34.732484 | D45: =SOTP!E56 -> 35.523783 | E45: =SOTP!F56 -> 36.445995 | F45: =SOTP!G56 -> 37.534534
A48: ⑦ KEY SEGMENT FINANCIALS (FY2025 Actuals | Source: SpaceX S-1)
A49: Metric ($M) | B49: FY2023A | C49: FY2024A | D49: FY2025A | E49: Q1 2026A
...

Sheet SOTP
A1: SpaceX — Sum-of-the-Parts Valuation
A2: Sum-of-the-Parts DCF Valuation | S-1 Filed May 20, 2026 | $ in Millions (except per share)
A3: Segments: Connectivity (Starlink) + Space (Launch/Starship) + AI (X/xAI/Grok) | 20-Year DCF with Gordon Growth & Exit Multiple cross-check
A5: Scenarios are controlled on the COVER tab (B28:B30). This sheet reflects the selected case live.
A6: SEGMENT ENTERPRISE VALUE SUMMARY ($M)
A7: Segment | B7: Method 1 EV ¹ | C7: Method 2 EV ² | D7: Avg / Selected EV | E7: % of Total SOTP | F7: Comp Data Status
A8: Connectivity (Starlink) | B8: ='Conn DCF'!B88 -> 524537.59 | C8: ='Conn DCF'!C88 -> 347554.8 | D8: =(B8+C8)/2 -> 436046.2 | E8: =D8/$D$11 -> 0.7587289 | F8: =IF(N('Conn Comps'!K57)>0,"✓ LIVE "&TEXT('Conn Comps'!K57,"0.0x")&" EV/EBITDA","⚠ FALLBACK") -> ✓ LIVE 5.9x EV/EBITDA
A9: Space (Launch + Starship) | B9: ='Space DCF'!B88 -> 85853.059 | C9: ='Space DCF'!C88 -> 96914.802 | D9: =(B9+C9)/2 -> 91383.931 | E9: =D9/$D$11 -> 0.15900983 | F9: =IF(N('Space Comps'!K37)>0,"✓ LIVE "&TEXT('Space Comps'!K37,"0.0x")&" EV/EBITDA","⚠ FALLBACK") -> ✓ LIVE 15.1x EV/EBITDA
A10: AI (X / xAI / Grok) | B10: ='AI DCF'!B88 -> 37296.99 | C10: ='AI DCF'!C88 -> 57255.133 | D10: =(B10+C10)/2 -> 47276.062 | E10: =D10/$D$11 -> 0.082261271 | F10: =IF(N('AI Comps'!J47)>0,"✓ LIVE "&TEXT('AI Comps'!J47,"0.0x")&" EV/Rev (Tier 3)","⚠ FALLBACK") -> ✓ LIVE 3.2x EV/Rev (Tier 3)
A11: Total Enterprise Value (SOTP) | B11: =B8+B9+B10 -> 647687.64 | C11: =C8+C9+C10 -> 501724.74 | D11: =D8+D9+D10 -> 574706.19 | E11: =D11/$D$11 -> 1
B14: Gordon Growth | C14: Exit Multiple | D14: Average | F14: Note
A15: Total Enterprise Value (SOTP) | B15: =B11 -> 647687.64 | C15: =C11 -> 501724.74 | D15: =D11 -> 574706.19
A16: (–) Total Debt & Finance Leases | B16: -23286 | C16: =$B$16 -> -23286 | D16: =$B$16 -> -23286 | F16: S-1 Dec'25 BS
A17: (+) Cash & Marketable Securities | B17: 24747 | C17: =$B$17 -> 24747 | D17: =$B$17 -> 24747 | F17: S-1 Dec'25 BS
A18: (–) Redeemable Preferred Stock | B18: -38752 | C18: =$B$18 -> -38752 | D18: =$B$18 -> -38752 | F18: Pre-IPO; converts at IPO
A19: Post-IPO Preferred Conversion Adjustment | B19: 38752 | C19: =$B$19 -> 38752 | D19: =$B$19 -> 38752
A20: Equity Value | B20: =B15+B16+B17+B18+B19 -> 649148.64 | C20: =C15+C16+C17+C18+C19 -> 503185.74 | D20: =D15+D16+D17+D18+D19 -> 576167.19
A22: IMPLIED PRICE PER SHARE (Post-IPO Fully Diluted)
A23: Item | B23: Gordon Growth | C23: Exit Multiple | D23: Average | F23: Note
A24: Common Shares — Basic (Class A+B+C, S-1 Q1'26) | B24: 5798 | C24: =$B$24 -> 5798 | D24: =$B$24 -> 5798 | F24: Cl. A+B+C (S-1 Q1'26)
A25: Total Shares — Fully Diluted, Post-IPO | B25: 12960 | C25: =$B$25 -> 12960 | D25: =$B$25 -> 12960 | F25: $1.75T ÷ $135 reconciled
A26: Implied Price/Share — on Basic (understates) | B26: =B20/$B$24 -> 111.96079 | C26: =C20/$B$24 -> 86.786088 | D26: =D20/$B$24 -> 99.373437
A27: Implied Price/Share — Fully Diluted (primary) | B27: =B20/$B$25 -> 50.08863 | C27: =C20/$B$25 -> 38.82606 | D27: =D20/$B$25 -> 44.457345
A29: SOTP COMPONENT BREAKDOWN ($M)
A30: Segment | B30: EV (Avg) | C30: Per Share (Basic) | D30: % of Total EV | E30: Segment WACC | F30: Key Value Driver
A31: Connectivity (Starlink) | B31: =D8 -> 436046.2 | C31: =B31/$B$24 -> 75.206312 | D31: =B31/$B$34 -> 0.7587289 | E31: ='Conn DCF'!B45 -> 0.075445353 | F31: Subscriber growth + enterprise adoption; 63%+ EBITDA margins
A32: Space (Launch + Starship) | B32: =D9 -> 91383.931 | C32: =B32/$B$24 -> 15.761285 | D32: =B32/$B$34 -> 0.15900983 | E32: ='Space DCF'!B45 -> 0.079328832 | F32: Starship cost curve + reusability; long-term capex normalization
A33: AI (X / xAI) | B33: =D10 -> 47276.062 | C33: =B33/$B$24 -> 8.1538568 | D33: =B33/$B$34 -> 0.082261271 | E33: ='AI DCF'!B45 -> 0.11585358 | F33: Grok monetization + compute infra; margin ramp from -39% to +46%
A34: Total | B34: =D11 -> 574706.19 | C34: =B34/$B$24 -> 99.121454 | D34: 1
A36: KEY METRICS SNAPSHOT (FY2025 Actuals | Source: SpaceX S-1)
A37: Metric | B37: FY2023A | C37: FY2024A | D37: FY2025A | E37: Q1 2026 | F37: Note
A38: Total Revenue ($M) | B38: 10387 | C38: 14015 | D38: 18674 | E38: 4694 | F38: S-1 Consolidated Statements of Operations
A39: Connectivity ($M) | B39: 3869 | C39: 7599 | D39: 11387 | E39: 3257 | F39: Starlink Consumer + Enterprise/Gov't
A40: Space ($M) | B40: 3557 | C40: 3796 | D40: 4086 | E40: 619 | F40: Launch Services + Launch & Development
A41: AI ($M) | B41: 2961 | C41: 2620 | D41: 3201 | E41: 818 | F41: X advertising + AI Solutions & Infrastructure
A42: Total Capex ($M) | B42: -4415 | C42: -11163 | D42: -20737 | E42: -10107 | F42: Massive AI infra build (xAI: $12.7B in 2025)
A43: Operating Cash Flow ($M) | B43: 4520 | C43: 5776 | D43: 6785
A44: Net Income (Loss) ($M) | B44: -4628 | C44: 791 | D44: -4937 | E44: -4276 | F44: R&D ($8.6B) + AI losses dominate 2025
A45: Connectivity EBITDA Margin | B45: 0.5 | C45: 0.462 | D45: 0.629 | E45: 0.641 | F45: From S-1 Segment Adjusted EBITDA disclosure
A46: ¹ Method 1 = Gordon Growth (perpetuity) for Connectivity & Space; EV/Revenue multiple (PRIMARY) for AI — Gordon distorts on AI's loss-making early FCF.
...

Sheet Conn DCF
A1: SpaceX — Connectivity Segment DCF (Starlink)
A2: S-1 Filed May 20, 2026 | 20-Year Explicit Forecast FY2026E–FY2045E | $ in Millions
A5: SCENARIO SELECTOR | B5: =COVER!B28 -> 2 | C5: =IF(B5=1,"◀ BEAR",IF(B5=2,"◀ BASE","◀ BULL")) -> ◀ BASE | D5: (1 = Bear | 2 = Base | 3 = Bull)
A7: BEAR CASE ASSUMPTIONS
B8: FY2023A | C8: FY2024A | D8: FY2025A | E8: FY2026E | F8: FY2027E | G8: FY2028E | H8: FY2029E | I8: FY2030E | J8: FY2031E | K8: FY2032E | L8: FY2033E | M8: FY2034E | N8: FY2035E | O8: FY2036E | P8: FY2037E | Q8: FY2038E | R8: FY2039E | S8: FY2040E | T8: FY2041E | U8: FY2042E | V8: FY2043E | W8: FY2044E | X8: FY2045E
A9: Revenue Growth % (YoY) | E9: 0.28 | F9: 0.24 | G9: 0.2 | H9: 0.18 | I9: 0.15 | J9: 0.13 | K9: 0.11 | L9: 0.09 | M9: 0.08 | N9: 0.07 | O9: 0.06 | P9: 0.055 | Q9: 0.05 | R9: 0.045 | S9: 0.04 | T9: 0.038 | U9: 0.035 | V9: 0.032 | W9: 0.03 | X9: 0.025
A10: EBITDA Margin % | E10: 0.6 | F10: 0.61 | G10: 0.62 | H10: 0.63 | I10: 0.64 | J10: 0.64 | K10: 0.65 | L10: 0.65 | M10: 0.65 | N10: 0.65 | O10: 0.655 | P10: 0.655 | Q10: 0.66 | R10: 0.66 | S10: 0.66 | T10: 0.665 | U10: 0.665 | V10: 0.67 | W10: 0.67 | X10: 0.67
A11: D&A % of Revenue | E11: 0.195 | F11: 0.185 | G11: 0.175 | H11: 0.165 | I11: 0.155 | J11: 0.15 | K11: 0.145 | L11: 0.14 | M11: 0.135 | N11: 0.13 | O11: 0.13 | P11: 0.13 | Q11: 0.125 | R11: 0.125 | S11: 0.12 | T11: 0.12 | U11: 0.12 | V11: 0.12 | W11: 0.12 | X11: 0.12
A12: Capex % of Revenue | E12: 0.34 | F12: 0.3 | G12: 0.26 | H12: 0.23 | I12: 0.2 | J12: 0.18 | K12: 0.16 | L12: 0.14 | M12: 0.12 | N12: 0.11 | O12: 0.105 | P12: 0.1 | Q12: 0.1 | R12: 0.095 | S12: 0.095 | T12: 0.09 | U12: 0.09 | V12: 0.09 | W12: 0.09 | X12: 0.09
A13: ΔNW Cap % of ΔRevenue | E13: 0.05 | F13: 0.05 | G13: 0.05 | H13: 0.05 | I13: 0.04 | J13: 0.04 | K13: 0.04 | L13: 0.03 | M13: 0.03 | N13: 0.03 | O13: 0.03 | P13: 0.03 | Q13: 0.03 | R13: 0.025 | S13: 0.025 | T13: 0.025 | U13: 0.025 | V13: 0.025 | W13: 0.025 | X13: 0.025
A14: Terminal Growth Rate | B14: =WACC!D47 -> 0.025
A15: WACC | B15: =WACC!B47 -> 0.075445353
A17: BASE CASE ASSUMPTIONS
B18: FY2023A | C18: FY2024A | D18: FY2025A | E18: FY2026E | F18: FY2027E | G18: FY2028E | H18: FY2029E | I18: FY2030E | J18: FY2031E | K18: FY2032E | L18: FY2033E | M18: FY2034E | N18: FY2035E | O18: FY2036E | P18: FY2037E | Q18: FY2038E | R18: FY2039E | S18: FY2040E | T18: FY2041E | U18: FY2042E | V18: FY2043E | W18: FY2044E | X18: FY2045E
A19: Revenue Growth % (YoY) | E19: 0.38 | F19: 0.32 | G19: 0.26 | H19: 0.22 | I19: 0.18 | J19: 0.15 | K19: 0.13 | L19: 0.11 | M19: 0.09 | N19: 0.08 | O19: 0.07 | P19: 0.065 | Q19: 0.06 | R19: 0.055 | S19: 0.05 | T19: 0.045 | U19: 0.04 | V19: 0.038 | W19: 0.035 | X19: 0.03
A20: EBITDA Margin % | E20: 0.63 | F20: 0.65 | G20: 0.66 | H20: 0.67 | I20: 0.68 | J20: 0.68 | K20: 0.68 | L20: 0.68 | M20: 0.68 | N20: 0.68 | O20: 0.685 | P20: 0.685 | Q20: 0.69 | R20: 0.69 | S20: 0.69 | T20: 0.695 | U20: 0.695 | V20: 0.7 | W20: 0.7 | X20: 0.7
A21: D&A % of Revenue | E21: 0.195 | F21: 0.185 | G21: 0.175 | H21: 0.165 | I21: 0.155 | J21: 0.15 | K21: 0.145 | L21: 0.14 | M21: 0.135 | N21: 0.13 | O21: 0.13 | P21: 0.125 | Q21: 0.125 | R21: 0.12 | S21: 0.12 | T21: 0.12 | U21: 0.115 | V21: 0.115 | W21: 0.115 | X21: 0.115
A22: Capex % of Revenue | E22: 0.32 | F22: 0.27 | G22: 0.23 | H22: 0.2 | I22: 0.17 | J22: 0.15 | K22: 0.13 | L22: 0.12 | M22: 0.11 | N22: 0.1 | O22: 0.095 | P22: 0.09 | Q22: 0.088 | R22: 0.085 | S22: 0.082 | T22: 0.08 | U22: 0.08 | V22: 0.08 | W22: 0.08 | X22: 0.08
A23: ΔNW Cap % of ΔRevenue | E23: 0.04 | F23: 0.04 | G23: 0.04 | H23: 0.04 | I23: 0.03 | J23: 0.03 | K23: 0.03 | L23: 0.03 | M23: 0.02 | N23: 0.02 | O23: 0.02 | P23: 0.02 | Q23: 0.02 | R23: 0.02 | S23: 0.02 | T23: 0.015 | U23: 0.015 | V23: 0.015 | W23: 0.015 | X23: 0.015
A24: Terminal Growth Rate | B24: =WACC!C47 -> 0.03
A25: WACC | B25: =WACC!B47 -> 0.075445353
A27: BULL CASE ASSUMPTIONS
B28: FY2023A | C28: FY2024A | D28: FY2025A | E28: FY2026E | F28: FY2027E | G28: FY2028E | H28: FY2029E | I28: FY2030E | J28: FY2031E | K28: FY2032E | L28: FY2033E | M28: FY2034E | N28: FY2035E | O28: FY2036E | P28: FY2037E | Q28: FY2038E | R28: FY2039E | S28: FY2040E | T28: FY2041E | U28: FY2042E | V28: FY2043E | W28: FY2044E | X28: FY2045E
A29: Revenue Growth % (YoY) | E29: 0.48 | F29: 0.4 | G29: 0.33 | H29: 0.27 | I29: 0.22 | J29: 0.18 | K29: 0.15 | L29: 0.13 | M29: 0.11 | N29: 0.09 | O29: 0.085 | P29: 0.08 | Q29: 0.075 | R29: 0.07 | S29: 0.065 | T29: 0.06 | U29: 0.055 | V29: 0.05 | W29: 0.045 | X29: 0.04
A30: EBITDA Margin % | E30: 0.65 | F30: 0.67 | G30: 0.69 | H30: 0.7 | I30: 0.71 | J30: 0.71 | K30: 0.72 | L30: 0.72 | M30: 0.72 | N30: 0.72 | O30: 0.72 | P30: 0.72 | Q30: 0.725 | R30: 0.725 | S30: 0.73 | T30: 0.73 | U30: 0.73 | V30: 0.73 | W30: 0.73 | X30: 0.73
A31: D&A % of Revenue | E31: 0.195 | F31: 0.185 | G31: 0.175 | H31: 0.165 | I31: 0.155 | J31: 0.15 | K31: 0.145 | L31: 0.14 | M31: 0.135 | N31: 0.13 | O31: 0.13 | P31: 0.125 | Q31: 0.12 | R31: 0.12 | S31: 0.115 | T31: 0.115 | U31: 0.11 | V31: 0.11 | W31: 0.11 | X31: 0.11
A32: Capex % of Revenue | E32: 0.3 | F32: 0.25 | G32: 0.21 | H32: 0.18 | I32: 0.15 | J32: 0.13 | K32: 0.11 | L32: 0.1 | M32: 0.09 | N32: 0.09 | O32: 0.085 | P32: 0.082 | Q32: 0.08 | R32: 0.078 | S32: 0.075 | T32: 0.072 | U32: 0.07 | V32: 0.07 | W32: 0.07 | X32: 0.07
A33: ΔNW Cap % of ΔRevenue | E33: 0.03 | F33: 0.03 | G33: 0.03 | H33: 0.03 | I33: 0.02 | J33: 0.02 | K33: 0.02 | L33: 0.02 | M33: 0.02 | N33: 0.02 | O33: 0.02 | P33: 0.02 | Q33: 0.015 | R33: 0.015 | S33: 0.015 | T33: 0.015 | U33: 0.015 | V33: 0.015 | W33: 0.015 | X33: 0.015
A34: Terminal Growth Rate | B34: =WACC!E47 -> 0.035
A35: WACC | B35: =WACC!B47 -> 0.075445353
A37: SELECTED CASE ASSUMPTIONS (auto-updates with Scenario Selector)
B38: FY2023A | C38: FY2024A | D38: FY2025A | E38: FY2026E | F38: FY2027E | G38: FY2028E | H38: FY2029E | I38: FY2030E | J38: FY2031E | K38: FY2032E | L38: FY2033E | M38: FY2034E | N38: FY2035E | O38: FY2036E | P38: FY2037E | Q38: FY2038E | R38: FY2039E | S38: FY2040E | T38: FY2041E | U38: FY2042E | V38: FY2043E | W38: FY2044E | X38: FY2045E
A39: Revenue Growth % (YoY) | E39: =IF($B$5=1,E9,IF($B$5=2,E19,E29)) -> 0.38 | F39: =IF($B$5=1,F9,IF($B$5=2,F19,F29)) -> 0.32 | G39: =IF($B$5=1,G9,IF($B$5=2,G19,G29)) -> 0.26 | H39: =IF($B$5=1,H9,IF($B$5=2,H19,H29)) -> 0.22 | I39: =IF($B$5=1,I9,IF($B$5=2,I19,I29)) -> 0.18 | J39: =IF($B$5=1,J9,IF($B$5=2,J19,J29)) -> 0.15 | K39: =IF($B$5=1,K9,IF($B$5=2,K19,K29)) -> 0.13 | L39: =IF($B$5=1,L9,IF($B$5=2,L19,L29)) -> 0.11 | ... X39: =IF($B$5=1,X9,IF($B$5=2,X19,X29)) -> 0.03
A40: EBITDA Margin % | E40: =IF($B$5=1,E10,IF($B$5=2,E20,E30)) -> 0.63 | F40: =IF($B$5=1,F10,IF($B$5=2,F20,F30)) -> 0.65 | G40: =IF($B$5=1,G10,IF($B$5=2,G20,G30)) -> 0.66 | H40: =IF($B$5=1,H10,IF($B$5=2,H20,H30)) -> 0.67 | I40: =IF($B$5=1,I10,IF($B$5=2,I20,I30)) -> 0.68 | J40: =IF($B$5=1,J10,IF($B$5=2,J20,J30)) -> 0.68 | K40: =IF($B$5=1,K10,IF($B$5=2,K20,K30)) -> 0.68 | L40: =IF($B$5=1,L10,IF($B$5=2,L20,L30)) -> 0.68 | ... X40: =IF($B$5=1,X10,IF($B$5=2,X20,X30)) -> 0.7
A41: D&A % of Revenue | E41: =IF($B$5=1,E11,IF($B$5=2,E21,E31)) -> 0.195 | F41: =IF($B$5=1,F11,IF($B$5=2,F21,F31)) -> 0.185 | G41: =IF($B$5=1,G11,IF($B$5=2,G21,G31)) -> 0.175 | H41: =IF($B$5=1,H11,IF($B$5=2,H21,H31)) -> 0.165 | I41: =IF($B$5=1,I11,IF($B$5=2,I21,I31)) -> 0.155 | J41: =IF($B$5=1,J11,IF($B$5=2,J21,J31)) -> 0.15 | K41: =IF($B$5=1,K11,IF($B$5=2,K21,K31)) -> 0.145 | L41: =IF($B$5=1,L11,IF($B$5=2,L21,L31)) -> 0.14 | ... X41: =IF($B$5=1,X11,IF($B$5=2,X21,X31)) -> 0.115
A42: Capex % of Revenue | E42: =IF($B$5=1,E12,IF($B$5=2,E22,E32)) -> 0.32 | F42: =IF($B$5=1,F12,IF($B$5=2,F22,F32)) -> 0.27 | G42: =IF($B$5=1,G12,IF($B$5=2,G22,G32)) -> 0.23 | H42: =IF($B$5=1,H12,IF($B$5=2,H22,H32)) -> 0.2 | I42: =IF($B$5=1,I12,IF($B$5=2,I22,I32)) -> 0.17 | J42: =IF($B$5=1,J12,IF($B$5=2,J22,J32)) -> 0.15 | K42: =IF($B$5=1,K12,IF($B$5=2,K22,K32)) -> 0.13 | L42: =IF($B$5=1,L12,IF($B$5=2,L22,L32)) -> 0.12 | ... X42: =IF($B$5=1,X12,IF($B$5=2,X22,X32)) -> 0.08
A43: ΔNW Cap % of ΔRevenue | E43: =IF($B$5=1,E13,IF($B$5=2,E23,E33)) -> 0.04 | F43: =IF($B$5=1,F13,IF($B$5=2,F23,F33)) -> 0.04 | G43: =IF($B$5=1,G13,IF($B$5=2,G23,G33)) -> 0.04 | H43: =IF($B$5=1,H13,IF($B$5=2,H23,H33)) -> 0.04 | I43: =IF($B$5=1,I13,IF($B$5=2,I23,I33)) -> 0.03 | J43: =IF($B$5=1,J13,IF($B$5=2,J23,J33)) -> 0.03 | K43: =IF($B$5=1,K13,IF($B$5=2,K23,K33)) -> 0.03 | L43: =IF($B$5=1,L13,IF($B$5=2,L23,L33)) -> 0.03 | ... X43: =IF($B$5=1,X13,IF($B$5=2,X23,X33)) -> 0.015
A44: Terminal Growth Rate | B44: =IF($B$5=1,B14,IF($B$5=2,B24,B34)) -> 0.03
A45: WACC | B45: =IF($B$5=1,B15,IF($B$5=2,B25,B35)) -> 0.075445353
A47: CONNECTIVITY SEGMENT — INCOME STATEMENT & FREE CASH FLOW ($M)
...

Sheet Space DCF
A1: SpaceX — Space Segment DCF (Launch & Starship)
A2: S-1 Filed May 20, 2026 | 20-Year Explicit Forecast FY2026E–FY2045E | $ in Millions
A5: SCENARIO SELECTOR | B5: =COVER!B29 -> 2 | C5: =IF(B5=1,"◀ BEAR",IF(B5=2,"◀ BASE","◀ BULL")) -> ◀ BASE | D5: (1 = Bear | 2 = Base | 3 = Bull)
A7: BEAR CASE ASSUMPTIONS
B8: FY2023A | C8: FY2024A | D8: FY2025A | E8: FY2026E | F8: FY2027E | G8: FY2028E | H8: FY2029E | I8: FY2030E | J8: FY2031E | K8: FY2032E | L8: FY2033E | M8: FY2034E | N8: FY2035E | O8: FY2036E | P8: FY2037E | Q8: FY2038E | R8: FY2039E | S8: FY2040E | T8: FY2041E | U8: FY2042E | V8: FY2043E | W8: FY2044E | X8: FY2045E
A9: Revenue Growth % (YoY) | E9: 0.06 | F9: 0.08 | G9: 0.1 | H9: 0.12 | I9: 0.15 | J9: 0.15 | K9: 0.13 | L9: 0.12 | M9: 0.1 | N9: 0.08 | O9: 0.07 | P9: 0.06 | Q9: 0.05 | R9: 0.045 | S9: 0.04 | T9: 0.035 | U9: 0.03 | V9: 0.03 | W9: 0.028 | X9: 0.025
A10: EBITDA Margin % | E10: 0.1 | F10: 0.12 | G10: 0.15 | H10: 0.18 | I10: 0.22 | J10: 0.25 | K10: 0.27 | L10: 0.28 | M10: 0.29 | N10: 0.3 | O10: 0.31 | P10: 0.32 | Q10: 0.33 | R10: 0.34 | S10: 0.34 | T10: 0.35 | U10: 0.36 | V10: 0.37 | W10: 0.37 | X10: 0.38
A11: D&A % of Revenue | E11: 0.19 | F11: 0.18 | G11: 0.17 | H11: 0.16 | I11: 0.15 | J11: 0.14 | K11: 0.14 | L11: 0.13 | M11: 0.13 | N11: 0.12 | O11: 0.12 | P11: 0.12 | Q11: 0.115 | R11: 0.115 | S11: 0.11 | T11: 0.11 | U11: 0.11 | V11: 0.11 | W11: 0.11 | X11: 0.11
A12: Capex % of Revenue | E12: 0.85 | F12: 0.75 | G12: 0.65 | H12: 0.55 | I12: 0.45 | J12: 0.38 | K12: 0.32 | L12: 0.28 | M12: 0.24 | N12: 0.22 | O12: 0.21 | P12: 0.2 | Q12: 0.19 | R12: 0.18 | S12: 0.17 | T12: 0.16 | U12: 0.15 | V12: 0.14 | W12: 0.13 | X12: 0.12
A13: ΔNW Cap % of ΔRevenue | E13: 0.06 | F13: 0.06 | G13: 0.05 | H13: 0.05 | I13: 0.05 | J13: 0.04 | K13: 0.04 | L13: 0.03 | M13: 0.03 | N13: 0.03 | O13: 0.03 | P13: 0.03 | Q13: 0.025 | R13: 0.025 | S13: 0.025 | T13: 0.025 | U13: 0.02 | V13: 0.02 | W13: 0.02 | X13: 0.02
A14: Terminal Growth Rate | B14: =WACC!D48 -> 0.02
A15: WACC | B15: =WACC!B48 -> 0.079328832
A17: BASE CASE ASSUMPTIONS
B18: FY2023A | C18: FY2024A | D18: FY2025A | E18: FY2026E | F18: FY2027E | G18: FY2028E | H18: FY2029E | I18: FY2030E | J18: FY2031E | K18: FY2032E | L18: FY2033E | M18: FY2034E | N18: FY2035E | O18: FY2036E | P18: FY2037E | Q18: FY2038E | R18: FY2039E | S18: FY2040E | T18: FY2041E | U18: FY2042E | V18: FY2043E | W18: FY2044E | X18: FY2045E
A19: Revenue Growth % (YoY) | E19: 0.1 | F19: 0.14 | G19: 0.18 | H19: 0.22 | I19: 0.26 | J19: 0.22 | K19: 0.18 | L19: 0.15 | M19: 0.13 | N19: 0.11 | O19: 0.1 | P19: 0.09 | Q19: 0.08 | R19: 0.07 | S19: 0.06 | T19: 0.05 | U19: 0.045 | V19: 0.04 | W19: 0.035 | X19: 0.03
A20: EBITDA Margin % | E20: 0.14 | F20: 0.18 | G20: 0.24 | H20: 0.3 | I20: 0.36 | J20: 0.41 | K20: 0.45 | L20: 0.47 | M20: 0.48 | N20: 0.49 | O20: 0.5 | P20: 0.51 | Q20: 0.52 | R20: 0.52 | S20: 0.53 | T20: 0.54 | U20: 0.54 | V20: 0.55 | W20: 0.55 | X20: 0.56
A21: D&A % of Revenue | E21: 0.19 | F21: 0.18 | G21: 0.17 | H21: 0.16 | I21: 0.15 | J21: 0.14 | K21: 0.14 | L21: 0.13 | M21: 0.13 | N21: 0.12 | O21: 0.12 | P21: 0.115 | Q21: 0.115 | R21: 0.11 | S21: 0.11 | T21: 0.11 | U21: 0.105 | V21: 0.105 | W21: 0.105 | X21: 0.105
A22: Capex % of Revenue | E22: 0.75 | F22: 0.65 | G22: 0.55 | H22: 0.45 | I22: 0.36 | J22: 0.28 | K22: 0.22 | L22: 0.18 | M22: 0.15 | N22: 0.13 | O22: 0.125 | P22: 0.12 | Q22: 0.115 | R22: 0.11 | S22: 0.105 | T22: 0.1 | U22: 0.098 | V22: 0.095 | W22: 0.092 | X22: 0.09
A23: ΔNW Cap % of ΔRevenue | E23: 0.05 | F23: 0.05 | G23: 0.05 | H23: 0.04 | I23: 0.04 | J23: 0.04 | K23: 0.03 | L23: 0.03 | M23: 0.02 | N23: 0.02 | O23: 0.02 | P23: 0.02 | Q23: 0.02 | R23: 0.018 | S23: 0.018 | T23: 0.015 | U23: 0.015 | V23: 0.015 | W23: 0.015 | X23: 0.015
A24: Terminal Growth Rate | B24: =WACC!C48 -> 0.025
A25: WACC | B25: =WACC!B48 -> 0.079328832
A27: BULL CASE ASSUMPTIONS
B28: FY2023A | C28: FY2024A | D28: FY2025A | E28: FY2026E | F28: FY2027E | G28: FY2028E | H28: FY2029E | I28: FY2030E | J28: FY2031E | K28: FY2032E | L28: FY2033E | M28: FY2034E | N28: FY2035E | O28: FY2036E | P28: FY2037E | Q28: FY2038E | R28: FY2039E | S28: FY2040E | T28: FY2041E | U28: FY2042E | V28: FY2043E | W28: FY2044E | X28: FY2045E
A29: Revenue Growth % (YoY) | E29: 0.16 | F29: 0.22 | G29: 0.28 | H29: 0.32 | I29: 0.36 | J29: 0.3 | K29: 0.25 | L29: 0.2 | M29: 0.17 | N29: 0.14 | O29: 0.13 | P29: 0.12 | Q29: 0.11 | R29: 0.1 | S29: 0.09 | T29: 0.08 | U29: 0.07 | V29: 0.06 | W29: 0.05 | X29: 0.04
A30: EBITDA Margin % | E30: 0.18 | F30: 0.24 | G30: 0.32 | H30: 0.4 | I30: 0.46 | J30: 0.5 | K30: 0.52 | L30: 0.53 | M30: 0.54 | N30: 0.55 | O30: 0.56 | P30: 0.57 | Q30: 0.58 | R30: 0.59 | S30: 0.59 | T30: 0.6 | U30: 0.61 | V30: 0.61 | W30: 0.62 | X30: 0.62
A31: D&A % of Revenue | E31: 0.19 | F31: 0.18 | G31: 0.17 | H31: 0.16 | I31: 0.15 | J31: 0.14 | K31: 0.14 | L31: 0.13 | M31: 0.13 | N31: 0.12 | O31: 0.12 | P31: 0.115 | Q31: 0.11 | R31: 0.11 | S31: 0.105 | T31: 0.105 | U31: 0.1 | V31: 0.1 | W31: 0.1 | X31: 0.1
A32: Capex % of Revenue | E32: 0.7 | F32: 0.6 | G32: 0.5 | H32: 0.4 | I32: 0.31 | J32: 0.24 | K32: 0.19 | L32: 0.16 | M32: 0.13 | N32: 0.11 | O32: 0.11 | P32: 0.105 | Q32: 0.1 | R32: 0.098 | S32: 0.095 | T32: 0.092 | U32: 0.09 | V32: 0.088 | W32: 0.085 | X32: 0.08
A33: ΔNW Cap % of ΔRevenue | E33: 0.04 | F33: 0.04 | G33: 0.04 | H33: 0.03 | I33: 0.03 | J33: 0.03 | K33: 0.02 | L33: 0.02 | M33: 0.02 | N33: 0.02 | O33: 0.02 | P33: 0.018 | Q33: 0.018 | R33: 0.015 | S33: 0.015 | T33: 0.015 | U33: 0.012 | V33: 0.012 | W33: 0.012 | X33: 0.012
A34: Terminal Growth Rate | B34: =WACC!E48 -> 0.03
A35: WACC | B35: =WACC!B48 -> 0.079328832
A37: SELECTED CASE ASSUMPTIONS
B38: FY2023A | C38: FY2024A | D38: FY2025A | E38: FY2026E | F38: FY2027E | G38: FY2028E | H38: FY2029E | I38: FY2030E | J38: FY2031E | K38: FY2032E | L38: FY2033E | M38: FY2034E | N38: FY2035E | O38: FY2036E | P38: FY2037E | Q38: FY2038E | R38: FY2039E | S38: FY2040E | T38: FY2041E | U38: FY2042E | V38: FY2043E | W38: FY2044E | X38: FY2045E
A39: Revenue Growth % (YoY) | E39: =IF($B$5=1,E9,IF($B$5=2,E19,E29)) -> 0.1 | F39: =IF($B$5=1,F9,IF($B$5=2,F19,F29)) -> 0.14 | G39: =IF($B$5=1,G9,IF($B$5=2,G19,G29)) -> 0.18 | H39: =IF($B$5=1,H9,IF($B$5=2,H19,H29)) -> 0.22 | I39: =IF($B$5=1,I9,IF($B$5=2,I19,I29)) -> 0.26 | J39: =IF($B$5=1,J9,IF($B$5=2,J19,J29)) -> 0.22 | K39: =IF($B$5=1,K9,IF($B$5=2,K19,K29)) -> 0.18 | L39: =IF($B$5=1,L9,IF($B$5=2,L19,L29)) -> 0.15 | ... X39: =IF($B$5=1,X9,IF($B$5=2,X19,X29)) -> 0.03
A40: EBITDA Margin % | E40: =IF($B$5=1,E10,IF($B$5=2,E20,E30)) -> 0.14 | F40: =IF($B$5=1,F10,IF($B$5=2,F20,F30)) -> 0.18 | G40: =IF($B$5=1,G10,IF($B$5=2,G20,G30)) -> 0.24 | H40: =IF($B$5=1,H10,IF($B$5=2,H20,H30)) -> 0.3 | I40: =IF($B$5=1,I10,IF($B$5=2,I20,I30)) -> 0.36 | J40: =IF($B$5=1,J10,IF($B$5=2,J20,J30)) -> 0.41 | K40: =IF($B$5=1,K10,IF($B$5=2,K20,K30)) -> 0.45 | L40: =IF($B$5=1,L10,IF($B$5=2,L20,L30)) -> 0.47 | ... X40: =IF($B$5=1,X10,IF($B$5=2,X20,X30)) -> 0.56
A41: D&A % of Revenue | E41: =IF($B$5=1,E11,IF($B$5=2,E21,E31)) -> 0.19 | F41: =IF($B$5=1,F11,IF($B$5=2,F21,F31)) -> 0.18 | G41: =IF($B$5=1,G11,IF($B$5=2,G21,G31)) -> 0.17 | H41: =IF($B$5=1,H11,IF($B$5=2,H21,H31)) -> 0.16 | I41: =IF($B$5=1,I11,IF($B$5=2,I21,I31)) -> 0.15 | J41: =IF($B$5=1,J11,IF($B$5=2,J21,J31)) -> 0.14 | K41: =IF($B$5=1,K11,IF($B$5=2,K21,K31)) -> 0.14 | L41: =IF($B$5=1,L11,IF($B$5=2,L21,L31)) -> 0.13 | ... X41: =IF($B$5=1,X11,IF($B$5=2,X21,X31)) -> 0.105
A42: Capex % of Revenue | E42: =IF($B$5=1,E12,IF($B$5=2,E22,E32)) -> 0.75 | F42: =IF($B$5=1,F12,IF($B$5=2,F22,F32)) -> 0.65 | G42: =IF($B$5=1,G12,IF($B$5=2,G22,G32)) -> 0.55 | H42: =IF($B$5=1,H12,IF($B$5=2,H22,H32)) -> 0.45 | I42: =IF($B$5=1,I12,IF($B$5=2,I22,I32)) -> 0.36 | J42: =IF($B$5=1,J12,IF($B$5=2,J22,J32)) -> 0.28 | K42: =IF($B$5=1,K12,IF($B$5=2,K22,K32)) -> 0.22 | L42: =IF($B$5=1,L12,IF($B$5=2,L22,L32)) -> 0.18 | ... X42: =IF($B$5=1,X12,IF($B$5=2,X22,X32)) -> 0.09
A43: ΔNW Cap % of ΔRevenue | E43: =IF($B$5=1,E13,IF($B$5=2,E23,E33)) -> 0.05 | F43: =IF($B$5=1,F13,IF($B$5=2,F23,F33)) -> 0.05 | G43: =IF($B$5=1,G13,IF($B$5=2,G23,G33)) -> 0.05 | H43: =IF($B$5=1,H13,IF($B$5=2,H23,H33)) -> 0.04 | I43: =IF($B$5=1,I13,IF($B$5=2,I23,I33)) -> 0.04 | J43: =IF($B$5=1,J13,IF($B$5=2,J23,J33)) -> 0.04 | K43: =IF($B$5=1,K13,IF($B$5=2,K23,K33)) -> 0.03 | L43: =IF($B$5=1,L13,IF($B$5=2,L23,L33)) -> 0.03 | ... X43: =IF($B$5=1,X13,IF($B$5=2,X23,X33)) -> 0.015
A44: Terminal Growth Rate | B44: =IF($B$5=1,B14,IF($B$5=2,B24,B34)) -> 0.025
A45: WACC | B45: =IF($B$5=1,B15,IF($B$5=2,B25,B35)) -> 0.079328832
A47: SPACE SEGMENT — INCOME STATEMENT & FREE CASH FLOW ($M)
...

Sheet AI DCF
A1: SpaceX — AI Segment DCF (X / xAI / Grok)
A2: S-1 Filed May 20, 2026 | 20-Year Explicit Forecast FY2026E–FY2045E | $ in Millions
A3: ⚠ AI segment includes X (social/advertising), xAI (Grok/models), and compute infrastructure. Op losses reflect heavy investment phase; TV captures mature-state value.
A5: SCENARIO SELECTOR | B5: =COVER!B30 -> 2 | C5: =IF(B5=1,"◀ BEAR",IF(B5=2,"◀ BASE","◀ BULL")) -> ◀ BASE | D5: (1 = Bear | 2 = Base | 3 = Bull)
A7: BEAR CASE ASSUMPTIONS
B8: FY2023A | C8: FY2024A | D8: FY2025A | E8: FY2026E | F8: FY2027E | G8: FY2028E | H8: FY2029E | I8: FY2030E | J8: FY2031E | K8: FY2032E | L8: FY2033E | M8: FY2034E | N8: FY2035E | O8: FY2036E | P8: FY2037E | Q8: FY2038E | R8: FY2039E | S8: FY2040E | T8: FY2041E | U8: FY2042E | V8: FY2043E | W8: FY2044E | X8: FY2045E
A9: Revenue Growth % (YoY) | E9: 0.15 | F9: 0.2 | G9: 0.25 | H9: 0.28 | I9: 0.3 | J9: 0.28 | K9: 0.25 | L9: 0.22 | M9: 0.18 | N9: 0.15 | O9: 0.14 | P9: 0.13 | Q9: 0.12 | R9: 0.1 | S9: 0.09 | T9: 0.08 | U9: 0.07 | V9: 0.06 | W9: 0.05 | X9: 0.04
A10: EBITDA Margin % | E10: -0.3 | F10: -0.15 | G10: 0 | H10: 0.1 | I10: 0.18 | J10: 0.23 | K10: 0.27 | L10: 0.3 | M10: 0.32 | N10: 0.34 | O10: 0.36 | P10: 0.38 | Q10: 0.39 | R10: 0.4 | S10: 0.41 | T10: 0.42 | U10: 0.42 | V10: 0.43 | W10: 0.43 | X10: 0.44
A11: D&A % of Revenue | E11: 1.05 | F11: 0.9 | G11: 0.75 | H11: 0.62 | I11: 0.52 | J11: 0.44 | K11: 0.38 | L11: 0.33 | M11: 0.29 | N11: 0.26 | O11: 0.24 | P11: 0.22 | Q11: 0.2 | R11: 0.19 | S11: 0.18 | T11: 0.17 | U11: 0.16 | V11: 0.16 | W11: 0.15 | X11: 0.15
A12: Capex % of Revenue | E12: 3.6 | F12: 2.8 | G12: 2.1 | H12: 1.6 | I12: 1.2 | J12: 0.95 | K12: 0.78 | L12: 0.65 | M12: 0.55 | N12: 0.48 | O12: 0.44 | P12: 0.4 | Q12: 0.36 | R12: 0.33 | S12: 0.3 | T12: 0.27 | U12: 0.24 | V12: 0.22 | W12: 0.2 | X12: 0.18
A13: ΔNW Cap % of ΔRevenue | E13: 0.08 | F13: 0.07 | G13: 0.06 | H13: 0.06 | I13: 0.05 | J13: 0.05 | K13: 0.04 | L13: 0.04 | M13: 0.03 | N13: 0.03 | O13: 0.03 | P13: 0.03 | Q13: 0.025 | R13: 0.025 | S13: 0.025 | T13: 0.02 | U13: 0.02 | V13: 0.02 | W13: 0.02 | X13: 0.02
A14: Terminal Growth Rate | B14: =WACC!D49 -> 0.025
A15: WACC | B15: =WACC!B49 -> 0.11585358
A17: BASE CASE ASSUMPTIONS
B18: FY2023A | C18: FY2024A | D18: FY2025A | E18: FY2026E | F18: FY2027E | G18: FY2028E | H18: FY2029E | I18: FY2030E | J18: FY2031E | K18: FY2032E | L18: FY2033E | M18: FY2034E | N18: FY2035E | O18: FY2036E | P18: FY2037E | Q18: FY2038E | R18: FY2039E | S18: FY2040E | T18: FY2041E | U18: FY2042E | V18: FY2043E | W18: FY2044E | X18: FY2045E
A19: Revenue Growth % (YoY) | E19: 0.28 | F19: 0.38 | G19: 0.45 | H19: 0.48 | I19: 0.45 | J19: 0.38 | K19: 0.32 | L19: 0.27 | M19: 0.22 | N19: 0.18 | O19: 0.16 | P19: 0.15 | Q19: 0.13 | R19: 0.12 | S19: 0.1 | T19: 0.09 | U19: 0.08 | V19: 0.07 | W19: 0.06 | X19: 0.05
A20: EBITDA Margin % | E20: -0.15 | F20: 0.02 | G20: 0.12 | H20: 0.22 | I20: 0.3 | J20: 0.36 | K20: 0.4 | L20: 0.43 | M20: 0.45 | N20: 0.46 | O20: 0.48 | P20: 0.5 | Q20: 0.51 | R20: 0.52 | S20: 0.53 | T20: 0.54 | U20: 0.55 | V20: 0.56 | W20: 0.57 | X20: 0.58
A21: D&A % of Revenue | E21: 1.05 | F21: 0.9 | G21: 0.75 | H21: 0.62 | I21: 0.52 | J21: 0.44 | K21: 0.38 | L21: 0.33 | M21: 0.29 | N21: 0.26 | O21: 0.24 | P21: 0.22 | Q21: 0.2 | R21: 0.19 | S21: 0.18 | T21: 0.17 | U21: 0.16 | V21: 0.16 | W21: 0.15 | X21: 0.15
A22: Capex % of Revenue | E22: 3.2 | F22: 2.4 | G22: 1.8 | H22: 1.35 | I22: 1 | J22: 0.8 | K22: 0.65 | L22: 0.54 | M22: 0.46 | N22: 0.4 | O22: 0.36 | P22: 0.33 | Q22: 0.3 | R22: 0.27 | S22: 0.25 | T22: 0.22 | U22: 0.2 | V22: 0.18 | W22: 0.16 | X22: 0.15
A23: ΔNW Cap % of ΔRevenue | E23: 0.06 | F23: 0.06 | G23: 0.05 | H23: 0.05 | I23: 0.04 | J23: 0.04 | K23: 0.03 | L23: 0.03 | M23: 0.03 | N23: 0.02 | O23: 0.02 | P23: 0.02 | Q23: 0.02 | R23: 0.018 | S23: 0.018 | T23: 0.015 | U23: 0.015 | V23: 0.015 | W23: 0.015 | X23: 0.015
A24: Terminal Growth Rate | B24: =WACC!C49 -> 0.035
A25: WACC | B25: =WACC!B49 -> 0.11585358
A27: BULL CASE ASSUMPTIONS
B28: FY2023A | C28: FY2024A | D28: FY2025A | E28: FY2026E | F28: FY2027E | G28: FY2028E | H28: FY2029E | I28: FY2030E | J28: FY2031E | K28: FY2032E | L28: FY2033E | M28: FY2034E | N28: FY2035E | O28: FY2036E | P28: FY2037E | Q28: FY2038E | R28: FY2039E | S28: FY2040E | T28: FY2041E | U28: FY2042E | V28: FY2043E | W28: FY2044E | X28: FY2045E
A29: Revenue Growth % (YoY) | E29: 0.45 | F29: 0.6 | G29: 0.7 | H29: 0.7 | I29: 0.6 | J29: 0.5 | K29: 0.42 | L29: 0.35 | M29: 0.28 | N29: 0.22 | O29: 0.2 | P29: 0.18 | Q29: 0.16 | R29: 0.14 | S29: 0.12 | T29: 0.11 | U29: 0.1 | V29: 0.09 | W29: 0.07 | X29: 0.06
A30: EBITDA Margin % | E30: -0.1 | F30: -0.05 | G30: 0.05 | H30: 0.12 | I30: 0.2 | J30: 0.28 | K30: 0.35 | L30: 0.42 | M30: 0.48 | N30: 0.55 | O30: 0.57 | P30: 0.59 | Q30: 0.6 | R30: 0.61 | S30: 0.62 | T30: 0.63 | U30: 0.64 | V30: 0.65 | W30: 0.65 | X30: 0.66
A31: D&A % of Revenue | E31: 1.05 | F31: 0.9 | G31: 0.75 | H31: 0.62 | I31: 0.52 | J31: 0.44 | K31: 0.38 | L31: 0.33 | M31: 0.29 | N31: 0.26 | O31: 0.24 | P31: 0.22 | Q31: 0.2 | R31: 0.18 | S31: 0.17 | T31: 0.16 | U31: 0.15 | V31: 0.15 | W31: 0.14 | X31: 0.14
A32: Capex % of Revenue | E32: 2.9 | F32: 2.1 | G32: 1.55 | H32: 1.15 | I32: 0.85 | J32: 0.68 | K32: 0.55 | L32: 0.46 | M32: 0.39 | N32: 0.34 | O32: 0.3 | P32: 0.27 | Q32: 0.25 | R32: 0.22 | S32: 0.2 | T32: 0.18 | U32: 0.16 | V32: 0.15 | W32: 0.14 | X32: 0.13
A33: ΔNW Cap % of ΔRevenue | E33: 0.05 | F33: 0.05 | G33: 0.04 | H33: 0.04 | I33: 0.03 | J33: 0.03 | K33: 0.03 | L33: 0.02 | M33: 0.02 | N33: 0.02 | O33: 0.02 | P33: 0.018 | Q33: 0.018 | R33: 0.015 | S33: 0.015 | T33: 0.015 | U33: 0.012 | V33: 0.012 | W33: 0.012 | X33: 0.012
A34: Terminal Growth Rate | B34: =WACC!E49 -> 0.04
A35: WACC | B35: =WACC!B49 -> 0.11585358
A37: SELECTED CASE ASSUMPTIONS
B38: FY2023A | C38: FY2024A | D38: FY2025A | E38: FY2026E | F38: FY2027E | G38: FY2028E | H38: FY2029E | I38: FY2030E | J38: FY2031E | K38: FY2032E | L38: FY2033E | M38: FY2034E | N38: FY2035E | O38: FY2036E | P38: FY2037E | Q38: FY2038E | R38: FY2039E | S38: FY2040E | T38: FY2041E | U38: FY2042E | V38: FY2043E | W38: FY2044E | X38: FY2045E
A39: Revenue Growth % (YoY) | E39: =IF($B$5=1,E9,IF($B$5=2,E19,E29)) -> 0.28 | F39: =IF($B$5=1,F9,IF($B$5=2,F19,F29)) -> 0.38 | G39: =IF($B$5=1,G9,IF($B$5=2,G19,G29)) -> 0.45 | H39: =IF($B$5=1,H9,IF($B$5=2,H19,H29)) -> 0.48 | I39: =IF($B$5=1,I9,IF($B$5=2,I19,I29)) -> 0.45 | J39: =IF($B$5=1,J9,IF($B$5=2,J19,J29)) -> 0.38 | K39: =IF($B$5=1,K9,IF($B$5=2,K19,K29)) -> 0.32 | L39: =IF($B$5=1,L9,IF($B$5=2,L19,L29)) -> 0.27 | ... X39: =IF($B$5=1,X9,IF($B$5=2,X19,X29)) -> 0.05
A40: EBITDA Margin % | E40: =IF($B$5=1,E10,IF($B$5=2,E20,E30)) -> -0.15 | F40: =IF($B$5=1,F10,IF($B$5=2,F20,F30)) -> 0.02 | G40: =IF($B$5=1,G10,IF($B$5=2,G20,G30)) -> 0.12 | H40: =IF($B$5=1,H10,IF($B$5=2,H20,H30)) -> 0.22 | I40: =IF($B$5=1,I10,IF($B$5=2,I20,I30)) -> 0.3 | J40: =IF($B$5=1,J10,IF($B$5=2,J20,J30)) -> 0.36 | K40: =IF($B$5=1,K10,IF($B$5=2,K20,K30)) -> 0.4 | L40: =IF($B$5=1,L10,IF($B$5=2,L20,L30)) -> 0.43 | ... X40: =IF($B$5=1,X10,IF($B$5=2,X20,X30)) -> 0.58
A41: D&A % of Revenue | E41: =IF($B$5=1,E11,IF($B$5=2,E21,E31)) -> 1.05 | F41: =IF($B$5=1,F11,IF($B$5=2,F21,F31)) -> 0.9 | G41: =IF($B$5=1,G11,IF($B$5=2,G21,G31)) -> 0.75 | H41: =IF($B$5=1,H11,IF($B$5=2,H21,H31)) -> 0.62 | I41: =IF($B$5=1,I11,IF($B$5=2,I21,I31)) -> 0.52 | J41: =IF($B$5=1,J11,IF($B$5=2,J21,J31)) -> 0.44 | K41: =IF($B$5=1,K11,IF($B$5=2,K21,K31)) -> 0.38 | L41: =IF($B$5=1,L11,IF($B$5=2,L21,L31)) -> 0.33 | ... X41: =IF($B$5=1,X11,IF($B$5=2,X21,X31)) -> 0.15
A42: Capex % of Revenue | E42: =IF($B$5=1,E12,IF($B$5=2,E22,E32)) -> 3.2 | F42: =IF($B$5=1,F12,IF($B$5=2,F22,F32)) -> 2.4 | G42: =IF($B$5=1,G12,IF($B$5=2,G22,G32)) -> 1.8 | H42: =IF($B$5=1,H12,IF($B$5=2,H22,H32)) -> 1.35 | I42: =IF($B$5=1,I12,IF($B$5=2,I22,I32)) -> 1 | J42: =IF($B$5=1,J12,IF($B$5=2,J22,J32)) -> 0.8 | K42: =IF($B$5=1,K12,IF($B$5=2,K22,K32)) -> 0.65 | L42: =IF($B$5=1,L12,IF($B$5=2,L22,L32)) -> 0.54 | ... X42: =IF($B$5=1,X12,IF($B$5=2,X22,X32)) -> 0.15
A43: ΔNW Cap % of ΔRevenue | E43: =IF($B$5=1,E13,IF($B$5=2,E23,E33)) -> 0.06 | F43: =IF($B$5=1,F13,IF($B$5=2,F23,F33)) -> 0.06 | G43: =IF($B$5=1,G13,IF($B$5=2,G23,G33)) -> 0.05 | H43: =IF($B$5=1,H13,IF($B$5=2,H23,H33)) -> 0.05 | I43: =IF($B$5=1,I13,IF($B$5=2,I23,I33)) -> 0.04 | J43: =IF($B$5=1,J13,IF($B$5=2,J23,J33)) -> 0.04 | K43: =IF($B$5=1,K13,IF($B$5=2,K23,K33)) -> 0.03 | L43: =IF($B$5=1,L13,IF($B$5=2,L23,L33)) -> 0.03 | ... X43: =IF($B$5=1,X13,IF($B$5=2,X23,X33)) -> 0.015
A44: Terminal Growth Rate | B44: =IF($B$5=1,B14,IF($B$5=2,B24,B34)) -> 0.035
A45: WACC | B45: =IF($B$5=1,B15,IF($B$5=2,B25,B35)) -> 0.11585358
...

Sheet WACC
A1: SpaceX — Weighted Average Cost of Capital
A2: May 2026 | Sum-of-the-Parts Segment WACCs | $M
A4: MACRO INPUTS
A5: Item | B5: Value | F5: Note
A6: Risk-Free Rate (10Y US Treasury) | B6: 0.0435 | F6: US Treasury, Jun 2026
A7: Equity Risk Premium | B7: 0.055 | F7: Damodaran Jan 2026 (US ERP)
A8: Tax Rate | B8: 0.21 | F8: US statutory; SpaceX has large NOL carryforwards
A9: Specific Risk Premium (Size / Illiquidity) | B9: 0.025 | F9: Pre-IPO illiquidity + size/execution risk; 2–3% typical for late-stage private
A11: COMPARABLE COMPANY BETA DERIVATION
A12: Company | B12: Levered β | C12: D/E Ratio | D12: Tax Rate | E12: Unlevered β | F12: Segment
A13: Iridium Communications (IRDM) | B13: 0.82 | C13: 0.35 | D13: 0.21 | E13: =B13/(1+(1-D13)*C13) -> 0.64238151 | F13: Space / Connectivity
A14: Viasat (VSAT) | B14: 1.15 | C14: 0.88 | D14: 0.21 | E14: =B14/(1+(1-D14)*C14) -> 0.67838603 | F14: Space / Connectivity
A15: Maxar Technologies | B15: 1.25 | C15: 0.75 | D15: 0.21 | E15: =B15/(1+(1-D15)*C15) -> 0.78492936 | F15: Space
A16: Rocket Lab (RKLB) | B16: 1.42 | C16: 0.18 | D16: 0.21 | E16: =B16/(1+(1-D16)*C16) -> 1.2432148 | F16: Space / Launch
A17: Meta Platforms (META) | B17: 1.28 | C17: 0.02 | D17: 0.21 | E17: =B17/(1+(1-D17)*C17) -> 1.2600906 | F17: AI / Social
A18: Alphabet (GOOGL) | B18: 1.05 | C18: 0 | D18: 0.21 | E18: =B18/(1+(1-D18)*C18) -> 1.05 | F18: AI / Infrastructure
A19: CoreWeave (CRWV) | B19: 1.65 | C19: 1.2 | D19: 0.21 | E19: =B19/(1+(1-D19)*C19) -> 0.84702259 | F19: AI Infrastructure
A21: UNLEVERED BETA BY SEGMENT (Comp-Driven — mature-stage tier median)
A22: Segment | B22: Selected Unlevered β | F22: Rationale
A23: Connectivity (Starlink) | B23: =IF(N('Conn Comps'!X57)>0,'Conn Comps'!X57,0.85) -> 0.20833333 | F23: Mature Wireless comp median unlevered β (fallback 0.85)
A24: Space (Launch) | B24: =IF(N('Space Comps'!X37)>0,'Space Comps'!X37,1.1) -> 0.26644722 | F24: Big-5 Defense comp median unlevered β (fallback 1.10)
A25: AI (X + xAI) | B25: =IF(N('AI Comps'!X47)>0,'AI Comps'!X47,1.35) -> 0.90384475 | F25: Social Media comp median unlevered β (fallback 1.35); excludes high-β neoclouds
A27: COST OF EQUITY BY SEGMENT
B28: Connectivity | C28: Space | D28: AI | F28: Formula
A29: Target D/E (post-IPO est.) | B29: 0.3 | C29: 0.45 | D29: 0.25 | F29: Based on Dec 2025 debt / est. post-IPO market cap by seg
A30: Relevered β | B30: =B23*(1+(1-$B$8)*B29) -> 0.25770833 | C30: =B24*(1+(1-$B$8)*C29) -> 0.3611692 | D30: =B25*(1+(1-$B$8)*D29) -> 1.0823541 | F30: βL = βU × (1 + (1-t) × D/E)
A31: Cost of Equity (CAPM) | B31: =$B$6+B30*$B$7+$B$9 -> 0.082673958 | C31: =$B$6+C30*$B$7+$B$9 -> 0.088364306 | D31: =$B$6+D30*$B$7+$B$9 -> 0.12802947 | F31: Ke = Rf + βL × ERP + SRP
A33: COST OF DEBT
B34: Connectivity | C34: Space | D34: AI | F34: Note
A35: Pre-Tax Cost of Debt | B35: 0.065 | C35: 0.075 | D35: 0.085 | F35: Based on SpaceX credit facility + X debt yields, Jun 2026
A36: After-Tax Cost of Debt | B36: =B35*(1-$B$8) -> 0.05135 | C36: =C35*(1-$B$8) -> 0.05925 | D36: =D35*(1-$B$8) -> 0.06715 | F36: Kd × (1-t)
A39: WACC CALCULATION
B40: Connectivity | C40: Space | D40: AI
A41: Equity Weight | B41: =1/(1+B29) -> 0.76923077 | C41: =1/(1+C29) -> 0.68965517 | D41: =1/(1+D29) -> 0.8 | F41: E/(E+D) = 1/(1+D/E)
A42: Debt Weight | B42: =B29/(1+B29) -> 0.23076923 | C42: =C29/(1+C29) -> 0.31034483 | D42: =D29/(1+D29) -> 0.2 | F42: D/(E+D) = (D/E)/(1+D/E)
A43: WACC | B43: =B31*B41+B36*B42 -> 0.075445353 | C43: =C31*C41+C36*C42 -> 0.079328832 | D43: =D31*D41+D36*D42 -> 0.11585358 | F43: WACC = Ke×We + Kd×Wd
A45: WACC SUMMARY (referenced by DCF sheets)
A46: Segment | B46: WACC | C46: Tg (Base) | D46: Tg (Bear) | E46: Tg (Bull)
A47: Connectivity | B47: =B43 -> 0.075445353 | C47: 0.03 | D47: 0.025 | E47: 0.035
A48: Space | B48: =C43 -> 0.079328832 | C48: 0.025 | D48: 0.02 | E48: 0.03
...

Sheet Ratios
A1: SpaceX — Financial Ratios & Credit Metrics
A2: Multiples at our intrinsic value vs. $135 IPO | $ in Millions | FY2025A actuals from S-1
A4: MARKET & VALUATION INPUTS
A5: Our Intrinsic Equity Value (avg, $M) | B5: =SOTP!D20 -> 576167.19
A6: Our Intrinsic EV (avg, $M) | B6: =SOTP!D11 -> 574706.19
A7: IPO Price / Share ($) | B7: =COVER!B5 -> 135
A8: Fully-Diluted Shares (M) | B8: =SOTP!B25 -> 12960
A9: IPO Market Cap ($M) | B9: =B7*B8 -> 1749600
A10: Net Debt ($M) | B10: =SOTP!B16+SOTP!B17 -> 1461
A11: IPO Enterprise Value ($M) | B11: =B9-B10 -> 1748139
A13: FY2025A FINANCIALS (S-1 actuals)
A14: Total Revenue ($M) | B14: =Actuals!D6 -> 18674
A15: Connectivity Revenue ($M) | B15: =Actuals!D7 -> 11387
A16: Space Revenue ($M) | B16: =Actuals!D8 -> 4086
A17: AI Revenue ($M) | B17: =Actuals!D9 -> 3201
A18: Consolidated Adj. EBITDA ($M) | B18: 6600
A19: Connectivity EBITDA ($M) | B19: =Actuals!D10 -> 7168
A20: Net Income (Loss) ($M) | B20: =Actuals!D15 -> -4937
A22: VALUATION MULTIPLES — Our Intrinsic vs. $135 IPO
A23: Multiple | B23: At Our Intrinsic | C23: At $135 IPO | E23: Comp Benchmark
A24: EV / Revenue (trailing) | B24: =B6/B14 -> 30.775741 | C24: =B11/B14 -> 93.613527 | E24: RKLB 118x | PLTR 81x | TSLA 17x
A25: EV / Connectivity Rev | B25: =SOTP!D8/B15 -> 38.293334 | C25: =B11/B15 -> 153.52059 | E25: (blended proxy)
A26: EV / EBITDA (Connectivity) | B26: =SOTP!D8/B19 -> 60.832338 | C26: =B11/B19 -> 243.881 | E26: Telecom 7-10x
A27: EV / EBITDA (consolidated) | B27: =B6/B18 -> 87.076695 | C27: =B11/B18 -> 264.86955 | E27: N/M if EBITDA low
A28: P / E | B28: N/M — net loss | C28: N/M — net loss | E28: SpaceX FY25 net loss $(4.9)B
A29: Market Cap / Revenue | B29: =B5/B14 -> 30.853978 | C29: =B9/B14 -> 93.691764 | E29: —
A31: BALANCE SHEET (Dec 2025, S-1 actuals)
A32: Cash & Marketable Securities ($M) | B32: 24747
A33: Total Current Assets ($M) | B33: 30952
A34: Total Assets ($M) | B34: 92079
A35: Total Current Liabilities ($M) | B35: 21400
A36: Total Debt & Finance Leases ($M) | B36: 23286
A37: Total Liabilities ($M) | B37: 50754
A38: Total Shareholders' Equity ($M) | B38: 2573
A40: FINANCIAL HEALTH RATIOS
A41: Ratio | B41: Value | E41: Note
A42: Current Ratio | B42: =B33/B35 -> 1.4463551 | E42: Current assets / current liabilities
A43: Quick Ratio (approx) | B43: =(B32)/B35 -> 1.1564019 | E43: Cash & securities / current liab
A44: Debt / Equity | B44: =B36/B38 -> 9.050136 | E44: Total debt / shareholders' equity
A45: Debt / EBITDA | B45: =B36/B18 -> 3.5281818 | E45: Leverage vs consolidated adj. EBITDA
...

Sheet Graphs
A1: SpaceX — Exhibits & Charts
T3: Segment EV Contribution ($B) | W3: Valuation Comparison — All Sources ($B)
T4: Segment | U4: Avg EV ($B) | W4: Source | X4: Equity/EV Value ($B)
T5: Connectivity | U5: =SOTP!D8/1000 -> 436.0462 | W5: IPO ($135) | X5: 1750
T6: Space | U6: =SOTP!D9/1000 -> 91.383931 | W6: ARK (2030 FV) | X6: 2500
T7: AI | U7: =SOTP!D10/1000 -> 47.276062 | W7: Morningstar | X7: 780
W8: M&I SOTP | X8: 429
W9: Rifat's DCF (Gordon) | X9: =SOTP!B20/1000 -> 649.14864
W10: Rifat's DCF (Avg) | X10: =SOTP!D20/1000 -> 576.16719

Sheet Conn Comps
A1: SpaceX — Connectivity Comparable Companies
A2: Comparable Public Companies by Maturity & Industry | Satellite Broadband + Telecom Infrastructure | $ in Millions
A3: Current-stage anchor = Satellite / LEO Broadband • Mature-stage anchor = Telecom Infrastructure. Input cells (blue) to be populated from terminal (CapIQ/Bloomberg).
A5: TIER 1 — PUBLIC SATELLITE OPERATORS (current-stage anchor)
A6: Name | B6: Ticker | C6: Mkt Cap | D6: Enterprise | E6: LTM | F6: Gross | G6: EBITDA | H6: Capex % | I6: 3-Yr Ann. | J6: TEV / | K6: TEV / | M6: # Subs | N6: ARPU | P6: Levered | Q6: Debt | R6: % Debt | S6: Preferred | T6: % Pref | U6: Equity | V6: % Equity | W6: Tax | X6: Unlevered
C7: ($M) | D7: Value ($M) | E7: Revenue ($M) | F7: Margin | G7: Margin | H7: Revenue | I7: Rev Growth | J7: Revenue | K7: EBITDA | M7: (M) | N7: ($) | P7: Beta | Q7: ($M) | S7: Stock ($M) | U7: Value ($M) | W7: Rate | X7: Beta
A8: Iridium Communications | B8: NasdaqGS:IRDM | C8: 3200 | D8: 4600 | E8: 830 | F8: 0.7195 | G8: 0.62 | H8: 0.045 | I8: 0.05 | J8: =IFERROR(IF(D8=0,"NM",D8/E8),"NM") -> 5.5421687 | K8: =IF(OR(G8<=0,E8=0,D8=0),"NM",IF(D8/(E8*G8)>100,"NM",D8/(E8*G8))) -> 8.9389817 | M8: 2.555 | N8: 27 | P8: 0.6 | Q8: 1810 | R8: =IFERROR(Q8/(Q8+S8+U8),"") -> 0.25138889 | S8: 0 | T8: =IFERROR(S8/($Q8+$S8+$U8),"") -> 0 | U8: 5390 | V8: =IFERROR(U8/(Q8+S8+U8),"") -> 0.74861111 | W8: 0.21 | X8: =IFERROR(P8/(1+(Q8/U8)*(1-W8)+S8/U8),"") -> 0.4742005
A9: EchoStar Corporation | B9: NasdaqGS:SATS | C9: 36100 | D9: 61430 | E9: 14800 | F9: 0.37 | G9: 0.37 | H9: 0.115 | I9: 0.11 | J9: =IFERROR(IF(D9=0,"NM",D9/E9),"NM") -> 4.1506757 | K9: =IF(OR(G9<=0,E9=0,D9=0),"NM",IF(D9/(E9*G9)>100,"NM",D9/(E9*G9))) -> 11.218042 | M9: 29.2 | N9: 40 | P9: 0.96 | Q9: 29240 | R9: =IFERROR(Q9/(Q9+S9+U9),"") -> 0.47130883 | S9: 0 | T9: =IFERROR(S9/($Q9+$S9+$U9),"") -> 0 | U9: 32800 | V9: =IFERROR(U9/(Q9+S9+U9),"") -> 0.52869117 | W9: 0.21 | X9: =IFERROR(P9/(1+(Q9/U9)*(1-W9)+S9/U9),"") -> 0.56329562
A10: Globalstar, Inc. | B10: NasdaqGS:GSAT | C10: 3000 | D10: 3500 | E10: 250 | F10: 0.6381 | G10: 0.4 | H10: 0.8 | I10: 0.1 | J10: =IFERROR(IF(D10=0,"NM",D10/E10),"NM") -> 14 | K10: =IF(OR(G10<=0,E10=0,D10=0),"NM",IF(D10/(E10*G10)>100,"NM",D10/(E10*G10))) -> 35 | M10: NM | N10: NM | P10: 2.6 | Q10: 546 | R10: =IFERROR(Q10/(Q10+S10+U10),"") -> 0.044953071 | S10: 0 | T10: =IFERROR(S10/($Q10+$S10+$U10),"") -> 0 | U10: 11600 | V10: =IFERROR(U10/(Q10+S10+U10),"") -> 0.95504693 | W10: 0.21 | X10: =IFERROR(P10/(1+(Q10/U10)*(1-W10)+S10/U10),"") -> 2.5067864
A11: AST SpaceMobile, Inc. | B11: NasdaqGS:ASTS | C11: 15600 | D11: 15100 | E11: 71 | F11: 0.4482 | G11: -2 | H11: 5 | I11: 0.15 | J11: =IFERROR(IF(D11=0,"NM",D11/E11),"NM") -> 212.67606 | K11: =IF(OR(G11<=0,E11=0,D11=0),"NM",IF(D11/(E11*G11)>100,"NM",D11/(E11*G11))) -> NM | M11: NM | N11: NM | P11: 2.6 | Q11: 2990 | R11: =IFERROR(Q11/(Q11+S11+U11),"") -> 0.096607431 | S11: 0 | T11: =IFERROR(S11/($Q11+$S11+$U11),"") -> 0 | U11: 27960 | V11: =IFERROR(U11/(Q11+S11+U11),"") -> 0.90339257 | W11: 0.21 | X11: =IFERROR(P11/(1+(Q11/U11)*(1-W11)+S11/U11),"") -> 2.3974593
A12: Viasat, Inc. | B12: NasdaqGS:VSAT | C12: 6640 | D12: 12000 | E12: 4500 | F12: 0.332 | G12: 0.3 | H12: 0.199 | I12: 0.08 | J12: =IFERROR(IF(D12=0,"NM",D12/E12),"NM") -> 2.6666667 | K12: =IF(OR(G12<=0,E12=0,D12=0),"NM",IF(D12/(E12*G12)>100,"NM",D12/(E12*G12))) -> 8.8888889 | M12: NM | N12: NM | P12: 1.37 | Q12: 7080 | R12: =IFERROR(Q12/(Q12+S12+U12),"") -> 0.43839009 | S12: 0 | T12: =IFERROR(S12/($Q12+$S12+$U12),"") -> 0 | U12: 9070 | V12: =IFERROR(U12/(Q12+S12+U12),"") -> 0.56160991 | W12: 0.21 | X12: =IFERROR(P12/(1+(Q12/U12)*(1-W12)+S12/U12),"") -> 0.84742075
A13: SES S.A. | B13: ENXTPA:SESG | C13: 6300 | D13: 12560 | E13: 2850 | F13: 0.6 | G13: 0.43 | H13: 0.5 | I13: 0.05 | J13: =IFERROR(IF(D13=0,"NM",D13/E13),"NM") -> 4.4070175 | K13: =IF(OR(G13<=0,E13=0,D13=0),"NM",IF(D13/(E13*G13)>100,"NM",D13/(E13*G13))) -> 10.248878 | M13: NM | N13: NM | P13: 0.51 | Q13: 3400 | R13: =IFERROR(Q13/(Q13+S13+U13),"") -> 0.57627119 | S13: 0 | T13: =IFERROR(S13/($Q13+$S13+$U13),"") -> 0 | U13: 2500 | V13: =IFERROR(U13/(Q13+S13+U13),"") -> 0.42372881 | W13: 0.21 | X13: =IFERROR(P13/(1+(Q13/U13)*(1-W13)+S13/U13),"") -> 0.24585422
A14: Eutelsat Communications | B14: ENXTPA:ETL | C14: 3840 | D14: 4810 | E14: 1230 | F14: 0.5 | G14: 0.3 | H14: 0.45 | I14: 0.08 | J14: =IFERROR(IF(D14=0,"NM",D14/E14),"NM") -> 3.9105691 | K14: =IF(OR(G14<=0,E14=0,D14=0),"NM",IF(D14/(E14*G14)>100,"NM",D14/(E14*G14))) -> 13.03523 | M14: NM | N14: NM | P14: 0.9 | Q14: 7300 | R14: =IFERROR(Q14/(Q14+S14+U14),"") -> 0.72277228 | S14: 0 | T14: =IFERROR(S14/($Q14+$S14+$U14),"") -> 0 | U14: 2800 | V14: =IFERROR(U14/(Q14+S14+U14),"") -> 0.27722772 | W14: 0.25 | X14: =IFERROR(P14/(1+(Q14/U14)*(1-W14)+S14/U14),"") -> 0.30453172
A15: Telesat Corporation | B15: NasdaqGS:TSAT | C15: 2460 | D15: 5500 | E15: 279 | F15: 0.65 | G15: 0.65 | H15: 0.35 | I15: 0.05 | J15: =IFERROR(IF(D15=0,"NM",D15/E15),"NM") -> 19.713262 | K15: =IF(OR(G15<=0,E15=0,D15=0),"NM",IF(D15/(E15*G15)>100,"NM",D15/(E15*G15))) -> 30.328095 | M15: NM | N15: NM | P15: 2 | Q15: 4200 | R15: =IFERROR(Q15/(Q15+S15+U15),"") -> 0.87318087 | S15: 0 | T15: =IFERROR(S15/($Q15+$S15+$U15),"") -> 0 | U15: 610 | V15: =IFERROR(U15/(Q15+S15+U15),"") -> 0.12681913 | W15: 0.265 | X15: =IFERROR(P15/(1+(Q15/U15)*(1-W15)+S15/U15),"") -> 0.3299973
A17: Min: | C17: =IFERROR(MIN(C8:C15),"") -> 2460 | D17: =IFERROR(MIN(D8:D15),"") -> 3500 | E17: =IFERROR(MIN(E8:E15),"") -> 71 | F17: =IFERROR(MIN(F8:F15),"") -> 0.332 | G17: =IFERROR(MIN(G8:G15),"") -> -2 | H17: =IFERROR(MIN(H8:H15),"") -> 0.045 | I17: =IFERROR(MIN(I8:I15),"") -> 0.05 | J17: =IFERROR(_xlfn.AGGREGATE(5,6,J8:J15),"") -> 2.6666667 | K17: =IFERROR(MIN(K8:K15),"") -> 8.8888889 | M17: =IFERROR(IF(COUNTA(M8:M15)=0,"",MIN(M8:M15)),"") -> 2.555 | N17: =IFERROR(IF(COUNTA(N8:N15)=0,"",MIN(N8:N15)),"") -> 27 | P17: =IFERROR(MIN(P8:P15),"") -> 0.51 | Q17: =IFERROR(MIN(Q8:Q15),"") -> 546 | R17: =IFERROR(MIN(R8:R15),"") -> 0.044953071 | S17: =IFERROR(MIN(S8:S15),"") -> 0 | T17: =IFERROR(MIN(T8:T15),"") -> 0 | U17: =IFERROR(MIN(U8:U15),"") -> 610 | V17: =IFERROR(MIN(V8:V15),"") -> 0.12681913 | W17: =IFERROR(MIN(W8:W15),"") -> 0.21 | X17: =IFERROR(MIN(X8:X15),"") -> 0.24585422
A18: 25th Pctl: | C18: =IFERROR(QUARTILE(C8:C15,1),"") -> 3150 | D18: =IFERROR(QUARTILE(D8:D15,1),"") -> 4757.5 | E18: =IFERROR(QUARTILE(E8:E15,1),"") -> 271.75 | F18: =IFERROR(QUARTILE(F8:F15,1),"") -> 0.42865 | G18: =IFERROR(QUARTILE(G8:G15,1),"") -> 0.3 | H18: =IFERROR(QUARTILE(H8:H15,1),"") -> 0.178 | I18: =IFERROR(QUARTILE(I8:I15,1),"") -> 0.05 | J18: =IFERROR(QUARTILE(J8:J15,1),"") -> 4.090649 | K18: =QUARTILE((K8,K9,K10,K12,K13,K14,K15),1) -> 9.5939299 | M18: =IFERROR(QUARTILE(M8:M15,1),"") -> 9.21625 | N18: =IFERROR(QUARTILE(N8:N15,1),"") -> 30.25 | P18: =IFERROR(QUARTILE(P8:P15,1),"") -> 0.825 | Q18: =IFERROR(QUARTILE(Q8:Q15,1),"") -> 2695 | R18: =IFERROR(QUARTILE(R8:R15,1),"") -> 0.21269352 | S18: =IFERROR(QUARTILE(S8:S15,1),"") -> 0 | T18: =IFERROR(QUARTILE(T8:T15,1),"") -> 0 | U18: =IFERROR(QUARTILE(U8:U15,1),"") -> 2725 | V18: =IFERROR(QUARTILE(V8:V15,1),"") -> 0.38710354 | W18: =IFERROR(QUARTILE(W8:W15,1),"") -> 0.21 | X18: =IFERROR(QUARTILE(X8:X15,1),"") -> 0.3236309
A19: Median: | C19: =IFERROR(MEDIAN(C8:C15),"") -> 5070 | D19: =IFERROR(MEDIAN(D8:D15),"") -> 8750 | E19: =IFERROR(MEDIAN(E8:E15),"") -> 1030 | F19: =IFERROR(MEDIAN(F8:F15),"") -> 0.55 | G19: =IFERROR(MEDIAN(G8:G15),"") -> 0.385 | H19: =IFERROR(MEDIAN(H8:H15),"") -> 0.4 | I19: =IFERROR(MEDIAN(I8:I15),"") -> 0.08 | J19: =IFERROR(QUARTILE(J8:J15,2),"") -> 4.9745931 | K19: =QUARTILE((K8,K9,K10,K12,K13,K14,K15),2) -> 11.218042 | M19: =IFERROR(MEDIAN(M8:M15),"") -> 15.8775 | N19: =IFERROR(MEDIAN(N8:N15),"") -> 33.5 | P19: =IFERROR(MEDIAN(P8:P15),"") -> 1.165 | Q19: =IFERROR(MEDIAN(Q8:Q15),"") -> 3800 | R19: =IFERROR(MEDIAN(R8:R15),"") -> 0.45484946 | S19: =IFERROR(MEDIAN(S8:S15),"") -> 0 | T19: =IFERROR(MEDIAN(T8:T15),"") -> 0 | U19: =IFERROR(MEDIAN(U8:U15),"") -> 7230 | V19: =IFERROR(MEDIAN(V8:V15),"") -> 0.54515054 | W19: =IFERROR(MEDIAN(W8:W15),"") -> 0.21 | X19: =IFERROR(MEDIAN(X8:X15),"") -> 0.51874806
A20: Mean: | C20: =IFERROR(AVERAGE(C8:C15),"") -> 9642.5 | D20: =IFERROR(AVERAGE(D8:D15),"") -> 14937.5 | E20: =IFERROR(AVERAGE(E8:E15),"") -> 3101.25 | F20: =IFERROR(AVERAGE(F8:F15),"") -> 0.532225 | G20: =IFERROR(AVERAGE(G8:G15),"") -> 0.13375 | H20: =IFERROR(AVERAGE(H8:H15),"") -> 0.932375 | I20: =IFERROR(AVERAGE(I8:I15),"") -> 0.08375 | J20: =IFERROR(_xlfn.AGGREGATE(1,6,J8:J15),"") -> 33.383302 | K20: =IFERROR(AVERAGE(K8:K15),"") -> 16.808302 | M20: =IFERROR(AVERAGE(M8:M15),"") -> 15.8775 | N20: =IFERROR(AVERAGE(N8:N15),"") -> 33.5 | P20: =IFERROR(AVERAGE(P8:P15),"") -> 1.4425 | Q20: =IFERROR(AVERAGE(Q8:Q15),"") -> 7070.75 | R20: =IFERROR(AVERAGE(R8:R15),"") -> 0.43435908 | S20: =IFERROR(AVERAGE(S8:S15),"") -> 0 | T20: =IFERROR(AVERAGE(T8:T15),"") -> 0 | U20: =IFERROR(AVERAGE(U8:U15),"") -> 11591.25 | V20: =IFERROR(AVERAGE(V8:V15),"") -> 0.56564092 | W20: =IFERROR(AVERAGE(W8:W15),"") -> 0.221875 | X20: =IFERROR(AVERAGE(X8:X15),"") -> 0.95869323
A21: 75th Pctl: | C21: =IFERROR(QUARTILE(C8:C15,3),"") -> 8880 | D21: =IFERROR(QUARTILE(D8:D15,3),"") -> 13195 | E21: =IFERROR(QUARTILE(E8:E15,3),"") -> 3262.5 | F21: =IFERROR(QUARTILE(F8:F15,3),"") -> 0.641075 | G21: =IFERROR(QUARTILE(G8:G15,3),"") -> 0.4775 | H21: =IFERROR(QUARTILE(H8:H15,3),"") -> 0.575 | I21: =IFERROR(QUARTILE(I8:I15,3),"") -> 0.1025 | J21: =IFERROR(QUARTILE(J8:J15,3),"") -> 15.428315 | K21: =QUARTILE((K8,K9,K10,K12,K13,K14,K15),3) -> 21.681663 | M21: =IFERROR(QUARTILE(M8:M15,3),"") -> 22.53875 | N21: =IFERROR(QUARTILE(N8:N15,3),"") -> 36.75 | P21: =IFERROR(QUARTILE(P8:P15,3),"") -> 2.15 | Q21: =IFERROR(QUARTILE(Q8:Q15,3),"") -> 7135 | R21: =IFERROR(QUARTILE(R8:R15,3),"") -> 0.61289646 | S21: =IFERROR(QUARTILE(S8:S15,3),"") -> 0 | T21: =IFERROR(QUARTILE(T8:T15,3),"") -> 0 | U21: =IFERROR(QUARTILE(U8:U15,3),"") -> 15690 | V21: =IFERROR(QUARTILE(V8:V15,3),"") -> 0.78730648 | W21: =IFERROR(QUARTILE(W8:W15,3),"") -> 0.22 | X21: =IFERROR(QUARTILE(X8:X15,3),"") -> 1.2349304
A22: Max: | C22: =IFERROR(MAX(C8:C15),"") -> 36100 | D22: =IFERROR(MAX(D8:D15),"") -> 61430 | E22: =IFERROR(MAX(E8:E15),"") -> 14800 | F22: =IFERROR(MAX(F8:F15),"") -> 0.7195 | G22: =IFERROR(MAX(G8:G15),"") -> 0.65 | H22: =IFERROR(MAX(H8:H15),"") -> 5 | I22: =IFERROR(MAX(I8:I15),"") -> 0.15 | J22: =IFERROR(_xlfn.AGGREGATE(4,6,J8:J15),"") -> 212.67606 | K22: =IFERROR(MAX(K8:K15),"") -> 35 | M22: =IFERROR(IF(COUNTA(M8:M15)=0,"",MAX(M8:M15)),"") -> 29.2 | N22: =IFERROR(IF(COUNTA(N8:N15)=0,"",MAX(N8:N15)),"") -> 40 | P22: =IFERROR(MAX(P8:P15),"") -> 2.6 | Q22: =IFERROR(MAX(Q8:Q15),"") -> 29240 | R22: =IFERROR(MAX(R8:R15),"") -> 0.87318087 | S22: =IFERROR(MAX(S8:S15),"") -> 0 | T22: =IFERROR(MAX(T8:T15),"") -> 0 | U22: =IFERROR(MAX(U8:U15),"") -> 32800 | V22: =IFERROR(MAX(V8:V15),"") -> 0.95504693 | W22: =IFERROR(MAX(W8:W15),"") -> 0.265 | X22: =IFERROR(MAX(X8:X15),"") -> 2.5067864
A24: TIER 2 — EMERGING-MARKETS TELECOM / WIRELESS (>10% Projected Organic Revenue Growth)
A25: Name | B25: Ticker | C25: Mkt Cap | D25: Enterprise | E25: LTM | F25: Gross | G25: EBITDA | H25: Capex % | I25: 3-Yr Ann. | J25: TEV / | K25: TEV / | M25: # Subs | N25: ARPU | P25: Levered | Q25: Debt | R25: % Debt | S25: Preferred | T25: % Pref | U25: Equity | V25: % Equity | W25: Tax | X25: Unlevered
C26: ($M) | D26: Value ($M) | E26: Revenue ($M) | F26: Margin | G26: Margin | H26: Revenue | I26: Rev Growth | J26: Revenue | K26: EBITDA | M26: (M) | N26: ($) | P26: Beta | Q26: ($M) | S26: Stock ($M) | U26: Value ($M) | W26: Rate | X26: Beta
A27: Bharti Airtel Limited | B27: BSE:532454 | C27: 116130 | D27: 137956 | E27: 23300 | F27: 0.5 | G27: 0.38 | H27: 0.22 | I27: 0.22 | J27: =IF(OR(D27="",D27=0,E27="",E27=0),"NM",D27/E27) -> 5.9208584 | K27: =IF(OR(G27<=0,E27=0,D27=0),"NM",IF(D27/(E27*G27)>100,"NM",D27/(E27*G27))) -> 15.581206 | M27: 478 | N27: 3 | P27: 0.5 | Q27: 14000 | R27: =IFERROR(Q27/(Q27+S27+U27),"") -> 0.11070694 | S27: 0 | T27: =IFERROR(S27/(Q27+S27+U27),"") -> 0 | U27: 112460 | V27: =IFERROR(U27/(Q27+S27+U27),"") -> 0.88929306 | W27: 0.25 | X27: =IFERROR(P27/(1+(Q27/U27)*(1-W27)+S27/U27),"") -> 0.45730319
