Workbook

Sheet Exec Summary
A1: Space Exploration Technologies Corp. (SpaceX) | $SPCX | Valuation Executive Summary
A2: ="Prepared: "&TEXT(TODAY(),"d-mmm-yyyy")&" | Source: SpaceX S-1 (Filed 20-May-2026) " -> Prepared: 24-Jun-2026 | Source: SpaceX S-1 (Filed 20-May-2026)
A4: INVESTMENT THESIS
A6: SpaceX is pursuing an IPO at $135/share, implying a fully diluted market cap of ~$1.75T. The company operates three segments:
A7: (1) Connectivity (Starlink) – satellite broadband, ~60% of FY2025 revenue, highest margin segment growing 50%+ YoY
A8: (2) Space (Launch + Starship) – launch services and government contracts, ~22% of revenue, steady growth anchored by Falcon 9 cadence
A9: (3) AI (X / xAI / Grok) – social media and AI compute infrastructure, ~17% of revenue, pre-profit but scaling rapidly
A11: Our 3-segment SOTP DCF analysis uses 20-year explicit forecasts per segment with comp-driven WACCs and terminal values.
A12: Two methodologies are applied: (1) Gordon Growth / EV-Revenue and (2) Exit Multiple / Gordon cross-check.
A14: VALUATION CONCLUSION
A16: Measure | B16: Method 1 ¹ | C16: Method 2 ² | D16: Average | G16: Notes
A17: Total Enterprise Value ($M) | B17: =SOTP!B12 -> 609915.35 | C17: =SOTP!C12 -> 410450.07 | D17: =SOTP!D12 -> 615495.19 | G17: ¹ Gordon Growth (Conn/Space) + EV/Revenue (AI)
A18: Equity Value ($M) | B18: =SOTP!B23 -> 692766.35 | C18: =SOTP!C23 -> 493301.07 | D18: =SOTP!D23 -> 698346.19 | G18: ² Exit Multiple (Conn/Space) + Gordon (AI cross-check)
A19: Implied Price / Share (fully diluted) | B19: =B18/SOTP!B29 -> 53.12218 | C19: =C18/SOTP!C29 -> 37.826936 | D19: =D18/SOTP!D29 -> 53.550049 | G19: Fully diluted: 12,960M shares (preferred conversion + xAI merger + RSUs + IPO)
A20: IPO Reference Price | B20: =Dashboard!B5 -> 154 | C20: =B20 -> 154 | D20: =B20 -> 154
A21: Upside / (Downside) to IPO | B21: =B19/B20-1 -> -0.65505078 | C21: =C19/C20-1 -> -0.75437055 | D21: =D19/D20-1 -> -0.65227241
A22: Shares Outstanding – Fully Diluted (M) | B22: =SOTP!B29 -> 13041
A24: SEGMENT VALUATION BREAKDOWN
A26: Segment | B26: Avg EV ($M) | C26: % of SOTP | D26: WACC | E26: Tg | G26: Primary Methodology
A27: Connectivity (Starlink) | B27: =SOTP!D9 -> 558405.91 | C27: =SOTP!E9 -> 0.90724658 | D27: =WACC!B42 -> 0.063906891 | E27: =WACC!C42 -> 0.03 | G27: Gordon Growth perpetuity + EV/EBITDA exit cross-check
A28: Space (Launch + Starship) | B28: =SOTP!D10 -> 52422.72 | C28: =SOTP!E10 -> 0.085171616 | D28: =WACC!B43 -> 0.068984004 | E28: =WACC!C43 -> 0.025 | G28: Gordon Growth perpetuity + EV/EBITDA exit cross-check
A29: AI (X / xAI / Grok) | B29: =SOTP!D11 -> 4666.5647 | C29: =SOTP!E11 -> 0.0075818052 | D29: =WACC!B44 -> 0.10385358 | E29: =WACC!C44 -> 0.035 | G29: EV/Revenue multiple (primary) – Gordon distorts on loss-making FCF
A30: Total SOTP | B30: =SOTP!D12 -> 615495.19 | C30: =SOTP!E12 -> 1
A32: KEY ASSUMPTIONS (Base Case)
A34: Item | B34: Connectivity | C34: Space | D34: AI | G34: Source
A35: Forecast Horizon | B35: 20 years | C35: 20 years | D35: 20 years | G35: DCF sheet assumptions
A36: WACC | B36: =WACC!B42 -> 0.063906891 | C36: =WACC!B43 -> 0.068984004 | D36: =WACC!B44 -> 0.10385358 | G36: Comp-driven; WACC sheet
A37: Terminal Growth Rate | B37: =WACC!C42 -> 0.03 | C37: =WACC!C43 -> 0.025 | D37: =WACC!C44 -> 0.035 | G37: WACC sheet
A38: Risk-Free Rate | B38: =WACC!B7 -> 0.0435 | G38: 10Y UST, Jun 2026
A39: Equity Risk Premium | B39: =WACC!B8 -> 0.055 | G39: Damodaran implied ERP, Jan 2026
A40: Tax Rate | B40: =WACC!B9 -> 0.21 | G40: US statutory; large NOL carryforwards
A42: FY2025 ACTUALS (S-1 Source)
A44: Metric | B44: FY2025 | C44: YoY | G44: Note
A45: Total Revenue ($M) | B45: =SOTP!D50 -> 18674 | C45: =SOTP!D50/SOTP!C50-1 -> 0.33242954 | G45: Consolidated – 3 segments
A46: Connectivity | B46: =SOTP!D51 -> 11387 | C46: =SOTP!D51/SOTP!C51-1 -> 0.49848664 | G46: 60.9% of total; 63% EBITDA margin
A47: Space | B47: =SOTP!D52 -> 4086 | C47: =SOTP!D52/SOTP!C52-1 -> 0.076396207 | G47: 21.9% of total; Falcon 9 cadence + Starship
A48: AI | B48: =SOTP!D53 -> 3201 | C48: =SOTP!D53/SOTP!C53-1 -> 0.22175573 | G48: 17.1% of total; X ads + xAI compute
A49: Net Income ($M) | B49: =SOTP!D56 -> -4937 | G49: AI segment losses dominate; R&D $8.6B
A50: Operating Cash Flow ($M) | B50: =SOTP!D55 -> 6785 | G50: Cash-generative despite heavy capex cycle
A51: Total Capex ($M) | B51: =SOTP!D54 -> -20737 | G51: AI infra $12.7B = 61% of total capex
...

Sheet Dashboard
A1: Space Exploration Technologies Corp. (SpaceX) | $SPCX | Sum-of-the-Parts DCF Valuation
A2: 3-Segment SOTP (Connectivity + Space + AI) | 20-Year Explicit DCF | S-1 Filed May 20, 2026 | $ in Millions (except per share)
A4: ① ENTER PRICE TO SEE UPSIDE / DOWNSIDE
A5: Current Share Price ($) | B5: 154 | C5: ← Enter the current trading price here
A7: ② VALUATION SUMMARY (Base Case)
B9: Gordon Growth | C9: Exit Multiple | D9: Average | H9: Note
A10: Total SOTP Enterprise Value ($M) | B10: =SOTP!B12 -> 609915.35 | C10: =SOTP!C12 -> 410450.07 | D10: =SOTP!D12 -> 615495.19
A11: (+) Net Cash (Cash − Total Debt) ($M) | B11: =SOTP!B18+SOTP!B19 -> -3149 | C11: =SOTP!C18+SOTP!C19 -> -3149 | D11: =SOTP!D18+SOTP!D19 -> -3149
A12: Connectivity Segment EV ($M) | B12: =SOTP!B9 -> 558405.91 | C12: =SOTP!C9 -> 340341.16 | D12: =SOTP!D9 -> 558405.91 | H12: =TEXT(D12/D10,"0%")&" of avg SOTP EV" -> 91% of avg SOTP EV
A13: Space Segment EV ($M) | B13: =SOTP!B10 -> 49217.277 | C13: =SOTP!C10 -> 59902.088 | D13: =SOTP!D10 -> 52422.72 | H13: =TEXT(D13/D10,"0%")&" of avg SOTP EV" -> 9% of avg SOTP EV
A14: AI Segment EV ($M) | B14: =SOTP!B11 -> 2292.1662 | C14: =SOTP!C11 -> 10206.828 | D14: =SOTP!D11 -> 4666.5647 | H14: =TEXT(D14/D10,"0%")&" of avg SOTP EV – wide range" -> 1% of avg SOTP EV – wide range
A15: Equity Value ($M) | B15: =SOTP!B23 -> 692766.35 | C15: =SOTP!C23 -> 493301.07 | D15: =SOTP!D23 -> 698346.19 | H15: After debt, cash, pref conversion
A17: Implied Share Price | B17: Gordon Growth | C17: Exit Multiple | D17: Average | H17: Shares Basis
A18: Basic – Common only (5,798M) | B18: =SOTP!B30 -> 119.48368 | C18: =SOTP!C30 -> 85.081247 | D18: =SOTP!D30 -> 120.44605 | H18: Understates: excludes converted pref + xAI shares
A19: Fully Diluted, Post-IPO (12,960M) | B19: =SOTP!B31 -> 53.12218 | C19: =SOTP!C31 -> 37.826936 | D19: =SOTP!D31 -> 53.550049 | H19: Reconciled to actual $135 IPO / $1.75T – primary metric
A21: ③ UPSIDE / (DOWNSIDE) vs. ENTERED PRICE (Fully-Diluted shares – primary)
B23: Gordon Growth | C23: Exit Multiple | D23: Average
A24: Our Implied Price (Fully-Diluted) | B24: =B19 -> 53.12218 | C24: =C19 -> 37.826936 | D24: =D19 -> 53.550049
A25: Current / IPO Price | B25: =IF(B5="","—",B5) -> 154 | C25: =IF(B5="","—",B5) -> 154 | D25: =IF(B5="","—",B5) -> 154
A26: Implied Upside / (Downside) | B26: =IF(B5="","← Enter price",(B19/B5)-1) -> -0.65505078 | C26: =IF(B5="","← Enter price",(C19/B5)-1) -> -0.75437055 | D26: =IF(B5="","← Enter price",(D19/B5)-1) -> -0.65227241
A28: ④ SCENARIO SELECTORS (1=Bear, 2=Base, 3=Bull – changes all 3 segment DCFs simultaneously)
A30: Segment | B30: Scenario (1/2/3) | C30: Selected | D30: WACC | E30: Terminal Growth (Base) | F30: Time-Varying WACC | G30: → Terminal
A31: Connectivity (Starlink) | B31: 2 | C31: =IF(B31=1,"◀ BEAR",IF(B31=2,"◀ BASE","◀ BULL")) -> ◀ BASE | D31: =WACC!B37 -> 0.063906891 | E31: =WACC!C42 -> 0.03 | F31: ='Conn DCF'!E77 -> 0.076352699 | G31: ='Conn DCF'!X77 -> 0.068413495
A32: Space (Launch + Starship) | B32: 2 | C32: =IF(B32=1,"◀ BEAR",IF(B32=2,"◀ BASE","◀ BULL")) -> ◀ BASE | D32: =WACC!C37 -> 0.068984004 | E32: =WACC!C43 -> 0.025 | F32: ='Space DCF'!E85 -> 0.12008989 | G32: ='Space DCF'!X85 -> 0.081760475
A33: AI (X / xAI / Grok) | B33: 2 | C33: =IF(B33=1,"◀ BEAR",IF(B33=2,"◀ BASE","◀ BULL")) -> ◀ BASE | D33: =WACC!D37 -> 0.10385358 | E33: =WACC!C44 -> 0.035 | F33: ='AI DCF'!E77 -> 0.15398861 | G33: ='AI DCF'!X77 -> 0.12056526
A34: ✓ Set scenarios here (B28:B30). 1=Bear, 2=Base, 3=Bull. Segment tabs follow automatically – whole valuation controlled from this page.
A36: ⑤ VALUATION SUMMARY (Implied Price/Share, Basic | Selected Scenario)
A38: Method | B38: Per Share (Basic) | H38: Note
A39: Gordon Growth (Perpetuity) | B39: =SOTP!B30 -> 119.48368 | C39: =SOTP!B30 -> 119.48368 | D39: =SOTP!B30 -> 119.48368 | H39: Changes with Scenario Selector (B28:B30 above)
A40: Exit Multiple | B40: =SOTP!C30 -> 85.081247 | C40: =SOTP!C30 -> 85.081247 | D40: =SOTP!C30 -> 85.081247
A41: Average (Gordon & Exit) | B41: =SOTP!D30 -> 120.44605 | C41: =SOTP!D30 -> 120.44605 | D41: =SOTP!D30 -> 120.44605
A43: ⑥ SENSITIVITY: Implied Price/Share (Fully-Diluted) – Connectivity WACC vs. Terminal Growth Rate (Base Case)
A45: WACC ↓ \ Terminal Growth Rate → | B45: =SOTP!C64 -> 0.0225 | C45: =SOTP!D64 -> 0.025 | D45: =SOTP!E64 -> 0.0275 | E45: =SOTP!F64 -> 0.03 | F45: =SOTP!G64 -> 0.0325 | G45: =SOTP!H64 -> 0.035 | H45: =SOTP!I64 -> 0.0375
A46: =SOTP!B65 -> 0.056406891 | B46: =SOTP!C65 -> 69.659843 | C46: =SOTP!D65 -> 72.757125 | D46: =SOTP!E65 -> 76.390142 | E46: =SOTP!F65 -> 80.711051 | F46: =SOTP!G65 -> 85.935655 | G46: =SOTP!H65 -> 92.380568 | H46: =SOTP!I65 -> 100.52986
A47: =SOTP!B66 -> 0.058906891 | B47: =SOTP!C66 -> 64.866783 | C47: =SOTP!D66 -> 67.421352 | D47: =SOTP!E66 -> 70.382611 | E47: =SOTP!F66 -> 73.856077 | F47: =SOTP!G66 -> 77.987224 | G47: =SOTP!H66 -> 82.982379 | H47: =SOTP!I66 -> 89.14425
A48: =SOTP!B67 -> 0.061406891 | B48: =SOTP!C67 -> 60.70767 | C48: =SOTP!D67 -> 62.836401 | D48: =SOTP!E67 -> 65.27904 | E48: =SOTP!F67 -> 68.110549 | F48: =SOTP!G67 -> 71.431822 | G48: =SOTP!H67 -> 75.38196 | H48: =SOTP!I67 -> 80.158248
A49: =SOTP!B68 -> 0.063906891 | B49: =SOTP!C68 -> 57.067054 | C49: =SOTP!D68 -> 58.856914 | D49: =SOTP!E68 -> 60.892587 | E49: =SOTP!F68 -> 63.228446 | F49: =SOTP!G68 -> 65.936176 | G49: =SOTP!H68 -> 69.112259 | H49: =SOTP!I68 -> 72.889717
A50: =SOTP!B69 -> 0.066406891 | B50: =SOTP!C69 -> 53.855805 | C50: =SOTP!D69 -> 55.372666 | D50: =SOTP!E69 -> 57.084462 | E50: =SOTP!F69 -> 59.03135 | F50: =SOTP!G69 -> 61.265331 | G50: =SOTP!H69 -> 63.854964 | H50: =SOTP!I69 -> 66.892524
A51: =SOTP!B70 -> 0.068906891 | B51: =SOTP!C70 -> 51.004024 | C51: =SOTP!D70 -> 52.29856 | D51: =SOTP!E70 -> 53.749415 | E51: =SOTP!F70 -> 55.386723 | F51: =SOTP!G70 -> 57.248892 | G51: =SOTP!H70 -> 59.385662 | H51: =SOTP!I70 -> 61.862608
A52: =SOTP!B71 -> 0.071406891 | B52: =SOTP!C71 -> 48.456126 | C52: =SOTP!D71 -> 49.567858 | D52: =SOTP!E71 -> 50.806191 | E52: =SOTP!F71 -> 52.194057 | F52: =SOTP!G71 -> 53.76028 | G52: =SOTP!H71 -> 55.541603 | H52: =SOTP!I71 -> 57.585605
...

Sheet SOTP
A1: SpaceX – Sum-of-the-Parts Valuation
A2: Sum-of-the-Parts DCF Valuation | S-1 Filed May 20, 2026 | $ in Millions (except per share)
A3: Segments: Connectivity (Starlink) + Space (Launch/Starship) + AI (X/xAI/Grok) | 20-Year DCF with Gordon Growth & Exit Multiple cross-check
A5: Scenarios are controlled on the COVER tab (B28:B30). This sheet reflects the selected case live.
A6: SEGMENT ENTERPRISE VALUE SUMMARY ($M)
A8: Segment | B8: Method 1 EV ¹ | C8: Method 2 EV ² | D8: Selected EV | E8: % of Total SOTP | F8: GG Weight | H8: Comp Data Status
A9: Connectivity (Starlink) | B9: ='Conn DCF'!B103 -> 558405.91 | C9: ='Conn DCF'!C103 -> 340341.16 | D9: =F9*B9+(1-F9)*C9 -> 558405.91 | E9: =D9/$D$12 -> 0.90724658 | F9: 1 | H9: =IF(N('Conn Comps'!K54)>0,"✓ LIVE "&TEXT('Conn Comps'!K54,"0.0x")&" EV/EBITDA","⚠ FALLBACK") -> ✓ LIVE 5.9x EV/EBITDA
A10: Space (Launch + Starship) | B10: ='Space DCF'!B111 -> 49217.277 | C10: ='Space DCF'!C111 -> 59902.088 | D10: =F10*B10+(1-F10)*C10 -> 52422.72 | E10: =D10/$D$12 -> 0.085171616 | F10: 0.7 | H10: =IF(N('Space Comps'!K35)>0,"✓ LIVE "&TEXT('Space Comps'!K35,"0.0x")&" EV/EBITDA","⚠ FALLBACK") -> ✓ LIVE 15.1x EV/EBITDA
A11: AI (X / xAI / Grok) | B11: ='AI DCF'!B103 -> 2292.1662 | C11: ='AI DCF'!C103 -> 10206.828 | D11: =F11*B11+(1-F11)*C11 -> 4666.5647 | E11: =D11/$D$12 -> 0.0075818052 | F11: 0.7 | H11: =IF(N('AI Comps'!J43)>0,"✓ LIVE "&TEXT('AI Comps'!J43,"0.0x")&" EV/Rev (Tier 3)","⚠ FALLBACK") -> ✓ LIVE 3.2x EV/Rev (Tier 3)
A12: Total Enterprise Value (SOTP) | B12: =B9+B10+B11 -> 609915.35 | C12: =C9+C10+C11 -> 410450.07 | D12: =D9+D10+D11 -> 615495.19 | E12: =D12/$D$12 -> 1
B16: Gordon Growth | C16: Exit Multiple | D16: Average | H16: Note
A17: Total Enterprise Value (SOTP) | B17: =B12 -> 609915.35 | C17: =C12 -> 410450.07 | D17: =D12 -> 615495.19
A18: (–) Total Debt & Finance Leases | B18: =-Historicals!D81-5000 -> -27896 | C18: =$B$18 -> -27896 | D18: =$B$18 -> -27896 | H18: S-1 Dec'25 BS
A19: (+) Cash & Marketable Securities | B19: =Historicals!D68 -> 24747 | C19: =$B$19 -> 24747 | D19: =$B$19 -> 24747 | H19: S-1 Dec'25 BS
A20: (–) Redeemable Preferred Stock | B20: =-Historicals!D79 -> -38752 | C20: =$B$20 -> -38752 | D20: =$B$20 -> -38752 | H20: Pre-IPO; converts at IPO
A21: Post-IPO Preferred Conversion Adjustment | B21: =-B20 -> 38752 | C21: =$B$21 -> 38752 | D21: =$B$21 -> 38752
A22: (+) IPO Proceeds (555.6M shares @ $135) | B22: 86000 | C22: =$B$22 -> 86000 | D22: =$B$22 -> 86000 | H22: 555.6M primary × $135
A23: Equity Value | B23: =B17+B18+B19+B20+B21+B22 -> 692766.35 | C23: =C17+C18+C19+C20+C21+C22 -> 493301.07 | D23: =D17+D18+D19+D20+D21+D22 -> 698346.19
A25: IMPLIED PRICE PER SHARE (Post-IPO Fully Diluted)
A27: Item | B27: Gordon Growth | C27: Exit Multiple | D27: Average | H27: Note
A28: Common Shares – Basic (Class A+B+C, S-1 Q1'26) | B28: 5798 | C28: =$B$28 -> 5798 | D28: =$B$28 -> 5798 | H28: Cl. A+B+C (S-1 Q1'26)
A29: Total Shares – Fully Diluted, Post-IPO | B29: =B93 -> 13041 | C29: =$B$29 -> 13041 | D29: =$B$29 -> 13041 | H29: $1.75T ÷ $135 reconciled
A30: Implied Price/Share – on Basic (understates) | B30: =B23/$B$28 -> 119.48368 | C30: =C23/$B$28 -> 85.081247 | D30: =D23/$B$28 -> 120.44605
A31: Implied Price/Share – Fully Diluted (primary) | B31: =B23/$B$29 -> 53.12218 | C31: =C23/$B$29 -> 37.826936 | D31: =D23/$B$29 -> 53.550049
A33: CURSOR PRO-FORMA (all-stock acquisition, pending Q3'26 close)
A34: (+) Cursor Acquisition EV (444M shares @ ~$135) | B34: 60000 | C34: =$B$34 -> 60000 | D34: =$B$34 -> 60000 | H34: All-stock; 3.4% dilution at IPO val
A35: Pro-Forma Equity Value | B35: =B23+B34 -> 752766.35 | C35: =C23+C34 -> 553301.07 | D35: =D23+D34 -> 758346.19
A36: Pro-Forma FD Shares (12,960 + 444M Cursor) | B36: =B29+444 -> 13485 | C36: =$B$36 -> 13485 | D36: =$B$36 -> 13485 | H36: $60B ÷ $135 = 444M new shares
A37: Pro-Forma Price/Share – Fully Diluted | B37: =B35/B36 -> 55.822495 | C37: =C35/C36 -> 41.030854 | D37: =D35/D36 -> 56.236277
A39: SOTP COMPONENT BREAKDOWN ($M)
A41: Segment | B41: EV (Avg) | C41: Per Share (Basic) | D41: % of Total EV | E41: Segment WACC | H41: Key Value Driver
A42: Connectivity (Starlink) | B42: =D9 -> 558405.91 | C42: =B42/$B$28 -> 96.310091 | D42: =B42/$B$45 -> 0.90724658 | E42: ='Conn DCF'!B46 -> 0.063906891 | H42: Subscriber growth + enterprise adoption; 63%+ EBITDA margins
A43: Space (Launch + Starship) | B43: =D10 -> 52422.72 | C43: =B43/$B$28 -> 9.0415178 | D43: =B43/$B$45 -> 0.085171616 | E43: ='Space DCF'!B50 -> 0.068984004 | H43: Starship cost curve + reusability; long-term capex normalization
A44: AI (X / xAI) | B44: =D11 -> 4666.5647 | C44: =B44/$B$28 -> 0.80485765 | D44: =B44/$B$45 -> 0.0075818052 | E44: ='AI DCF'!B42 -> 0.10385358 | H44: Grok monetization + compute infra; margin ramp from -39% to +46%
A45: Total | B45: =D12 -> 615495.19 | C45: =B45/$B$28 -> 106.15647 | D45: =SUM(D42:D44) -> 1
A47: KEY METRICS SNAPSHOT (FY2025 Actuals | Source: SpaceX S-1)
A49: Metric | B49: FY2023A | C49: FY2024A | D49: FY2025A | E49: Q1 2026 | H49: Note
A50: Total Revenue ($M) | B50: =Historicals!B8 -> 10387 | C50: =Historicals!C8 -> 14015 | D50: =Historicals!D8 -> 18674 | E50: =Historicals!J8 -> 4694 | H50: S-1 Consolidated Statements of Operations
A51: Connectivity ($M) | B51: =Historicals!B32 -> 3869 | C51: =Historicals!C32 -> 7599 | D51: =Historicals!D32 -> 11387 | E51: =Historicals!J32 -> 3257 | H51: Starlink Consumer + Enterprise/Gov't
A52: Space ($M) | B52: =Historicals!B29 -> 3557 | C52: =Historicals!C29 -> 3796 | D52: =Historicals!D29 -> 4086 | E52: =Historicals!J29 -> 619 | H52: Launch Services + Launch & Development
...

Sheet Conn DCF
A1: SpaceX – Connectivity Segment DCF (Starlink)
A2: S-1 Filed May 20, 2026 | 20-Year Explicit Forecast FY2026E–FY2045E | $ in Millions
A5: SCENARIO SELECTOR | B5: =Dashboard!B31 -> 2 | C5: =IF(B5=1,"◀ BEAR",IF(B5=2,"◀ BASE","◀ BULL")) -> ◀ BASE | D5: (1 = Bear | 2 = Base | 3 = Bull)
B6: FY2023A | C6: FY2024A | D6: FY2025A | E6: FY2026E | F6: FY2027E | G6: FY2028E | H6: FY2029E | I6: FY2030E | J6: FY2031E | K6: FY2032E | L6: FY2033E | M6: FY2034E | N6: FY2035E | O6: FY2036E | P6: FY2037E | Q6: FY2038E | R6: FY2039E | S6: FY2040E | T6: FY2041E | U6: FY2042E | V6: FY2043E | W6: FY2044E | X6: FY2045E
A8: BEAR CASE ASSUMPTIONS
A9: Revenue Growth % (YoY) | E9: 0.28 | F9: 0.24 | G9: 0.2 | H9: 0.18 | I9: 0.15 | J9: 0.13 | K9: 0.11 | L9: 0.09 | M9: 0.08 | N9: 0.07 | O9: 0.06 | P9: 0.055 | Q9: 0.05 | R9: 0.045 | S9: 0.04 | T9: 0.038 | U9: 0.035 | V9: 0.032 | W9: 0.03 | X9: 0.025
A10: EBITDA Margin % | E10: 0.6 | F10: 0.61 | G10: 0.62 | H10: 0.63 | I10: 0.64 | J10: 0.64 | K10: 0.65 | L10: 0.65 | M10: 0.65 | N10: 0.65 | O10: 0.655 | P10: 0.655 | Q10: 0.66 | R10: 0.66 | S10: 0.66 | T10: 0.665 | U10: 0.665 | V10: 0.67 | W10: 0.67 | X10: 0.67
A11: Capex % of Revenue | E11: 0.34 | F11: 0.3 | G11: 0.26 | H11: 0.23 | I11: 0.2 | J11: 0.18 | K11: 0.16 | L11: 0.14 | M11: 0.12 | N11: 0.11 | O11: 0.105 | P11: 0.1 | Q11: 0.1 | R11: 0.095 | S11: 0.095 | T11: 0.09 | U11: 0.09 | V11: 0.09 | W11: 0.09 | X11: 0.09
A12: ΔNW Cap % of ΔRevenue | E12: 0.05 | F12: 0.05 | G12: 0.05 | H12: 0.05 | I12: 0.04 | J12: 0.04 | K12: 0.04 | L12: 0.03 | M12: 0.03 | N12: 0.03 | O12: 0.03 | P12: 0.03 | Q12: 0.03 | R12: 0.025 | S12: 0.025 | T12: 0.025 | U12: 0.025 | V12: 0.025 | W12: 0.025 | X12: 0.025
A13: Active Fleet (End of Period) | E13: 10200 | F13: 11400 | G13: 12800 | H13: 13850 | I13: 14950 | J13: 16000 | K13: 16800 | L13: 17400 | M13: 18000 | N13: 18600 | O13: 18950 | P13: 19300 | Q13: 19650 | R13: 20000 | S13: 20350 | T13: 20550 | U13: 20750 | V13: 20950 | W13: 21150 | X13: 21350
A14: SBC (% of Revenue) | E14: 0.03 | F14: 0.03 | G14: 0.029 | H14: 0.029 | I14: 0.028 | J14: 0.028 | K14: 0.027 | L14: 0.027 | M14: 0.026 | N14: 0.026 | O14: 0.025 | P14: 0.025 | Q14: 0.024 | R14: 0.024 | S14: 0.023 | T14: 0.023 | U14: 0.022 | V14: 0.022 | W14: 0.021 | X14: 0.02
A15: Terminal Growth Rate | B15: =WACC!D42 -> 0.025
A16: WACC | B16: =WACC!B42 -> 0.063906891
A18: BASE CASE ASSUMPTIONS
A19: Revenue Growth % (YoY) | E19: 0.38 | F19: 0.32 | G19: 0.26 | H19: 0.22 | I19: 0.18 | J19: 0.15 | K19: 0.13 | L19: 0.11 | M19: 0.09 | N19: 0.08 | O19: 0.07 | P19: 0.065 | Q19: 0.06 | R19: 0.055 | S19: 0.05 | T19: 0.045 | U19: 0.04 | V19: 0.038 | W19: 0.035 | X19: 0.03
A20: EBITDA Margin % | E20: 0.63 | F20: 0.65 | G20: 0.66 | H20: 0.67 | I20: 0.68 | J20: 0.68 | K20: 0.68 | L20: 0.68 | M20: 0.68 | N20: 0.68 | O20: 0.685 | P20: 0.685 | Q20: 0.69 | R20: 0.69 | S20: 0.69 | T20: 0.695 | U20: 0.695 | V20: 0.7 | W20: 0.7 | X20: 0.7
A21: Capex % of Revenue | E21: 0.32 | F21: 0.27 | G21: 0.23 | H21: 0.2 | I21: 0.17 | J21: 0.15 | K21: 0.13 | L21: 0.12 | M21: 0.11 | N21: 0.1 | O21: 0.095 | P21: 0.09 | Q21: 0.088 | R21: 0.085 | S21: 0.082 | T21: 0.08 | U21: 0.08 | V21: 0.08 | W21: 0.08 | X21: 0.08
A22: ΔNW Cap % of ΔRevenue | E22: 0.04 | F22: 0.04 | G22: 0.04 | H22: 0.04 | I22: 0.03 | J22: 0.03 | K22: 0.03 | L22: 0.03 | M22: 0.02 | N22: 0.02 | O22: 0.02 | P22: 0.02 | Q22: 0.02 | R22: 0.02 | S22: 0.02 | T22: 0.015 | U22: 0.015 | V22: 0.015 | W22: 0.015 | X22: 0.015
A23: Active Fleet (End of Period) | E23: 11040 | F23: 12696 | G23: 14600 | H23: 16060 | I23: 17666 | J23: 19433 | K23: 20405 | L23: 21425 | M23: 22496 | N23: 23621 | O23: 24093 | P23: 24575 | Q23: 25067 | R23: 25568 | S23: 26079 | T23: 26340 | U23: 26603 | V23: 26869 | W23: 27138 | X23: 27409
A24: SBC (% of Revenue) | E24: 0.025 | F24: 0.025 | G24: 0.024 | H24: 0.024 | I24: 0.023 | J24: 0.023 | K24: 0.022 | L24: 0.022 | M24: 0.021 | N24: 0.021 | O24: 0.02 | P24: 0.02 | Q24: 0.019 | R24: 0.019 | S24: 0.018 | T24: 0.018 | U24: 0.017 | V24: 0.017 | W24: 0.016 | X24: 0.015
A25: Terminal Growth Rate | B25: =WACC!C42 -> 0.03
A26: WACC | B26: =WACC!B42 -> 0.063906891
A28: BULL CASE ASSUMPTIONS
A29: Revenue Growth % (YoY) | E29: 0.48 | F29: 0.4 | G29: 0.33 | H29: 0.27 | I29: 0.22 | J29: 0.18 | K29: 0.15 | L29: 0.13 | M29: 0.11 | N29: 0.09 | O29: 0.085 | P29: 0.08 | Q29: 0.075 | R29: 0.07 | S29: 0.065 | T29: 0.06 | U29: 0.055 | V29: 0.05 | W29: 0.045 | X29: 0.04
A30: EBITDA Margin % | E30: 0.65 | F30: 0.67 | G30: 0.69 | H30: 0.7 | I30: 0.71 | J30: 0.71 | K30: 0.72 | L30: 0.72 | M30: 0.72 | N30: 0.72 | O30: 0.72 | P30: 0.72 | Q30: 0.725 | R30: 0.725 | S30: 0.73 | T30: 0.73 | U30: 0.73 | V30: 0.73 | W30: 0.73 | X30: 0.73
A31: Capex % of Revenue | E31: 0.3 | F31: 0.25 | G31: 0.21 | H31: 0.18 | I31: 0.15 | J31: 0.13 | K31: 0.11 | L31: 0.1 | M31: 0.09 | N31: 0.09 | O31: 0.085 | P31: 0.082 | Q31: 0.08 | R31: 0.078 | S31: 0.075 | T31: 0.072 | U31: 0.07 | V31: 0.07 | W31: 0.07 | X31: 0.07
A32: ΔNW Cap % of ΔRevenue | E32: 0.03 | F32: 0.03 | G32: 0.03 | H32: 0.03 | I32: 0.02 | J32: 0.02 | K32: 0.02 | L32: 0.02 | M32: 0.02 | N32: 0.02 | O32: 0.02 | P32: 0.02 | Q32: 0.015 | R32: 0.015 | S32: 0.015 | T32: 0.015 | U32: 0.015 | V32: 0.015 | W32: 0.015 | X32: 0.015
A33: Active Fleet (End of Period) | E33: 12100 | F33: 14400 | G33: 17000 | H33: 19200 | I33: 21600 | J33: 24200 | K33: 25800 | L33: 27500 | M33: 29100 | N33: 30800 | O33: 31600 | P33: 32400 | Q33: 33250 | R33: 34100 | S33: 35000 | T33: 35500 | U33: 36000 | V33: 36500 | W33: 37000 | X33: 37500
A34: SBC (% of Revenue) | E34: 0.02 | F34: 0.02 | G34: 0.019 | H34: 0.019 | I34: 0.018 | J34: 0.018 | K34: 0.017 | L34: 0.017 | M34: 0.016 | N34: 0.016 | O34: 0.015 | P34: 0.015 | Q34: 0.014 | R34: 0.014 | S34: 0.013 | T34: 0.013 | U34: 0.012 | V34: 0.012 | W34: 0.011 | X34: 0.01
A35: Terminal Growth Rate | B35: =WACC!E42 -> 0.035
A36: WACC | B36: =WACC!B42 -> 0.063906891
A38: SELECTED CASE ASSUMPTIONS (auto-updates with Scenario Selector)
A39: Revenue Growth % (YoY) | E39: =IF($B$5=1,E9,IF($B$5=2,E19,E29)) -> 0.38 | F39: =IF($B$5=1,F9,IF($B$5=2,F19,F29)) -> 0.32 | G39: =IF($B$5=1,G9,IF($B$5=2,G19,G29)) -> 0.26 | H39: =IF($B$5=1,H9,IF($B$5=2,H19,H29)) -> 0.22 | I39: =IF($B$5=1,I9,IF($B$5=2,I19,I29)) -> 0.18 | J39: =IF($B$5=1,J9,IF($B$5=2,J19,J29)) -> 0.15 | K39: =IF($B$5=1,K9,IF($B$5=2,K19,K29)) -> 0.13 | L39: =IF($B$5=1,L9,IF($B$5=2,L19,L29)) -> 0.11 | ... X39: =IF($B$5=1,X9,IF($B$5=2,X19,X29)) -> 0.03
A40: EBITDA Margin % | E40: =IF($B$5=1,E10,IF($B$5=2,E20,E30)) -> 0.63 | F40: =IF($B$5=1,F10,IF($B$5=2,F20,F30)) -> 0.65 | G40: =IF($B$5=1,G10,IF($B$5=2,G20,G30)) -> 0.66 | H40: =IF($B$5=1,H10,IF($B$5=2,H20,H30)) -> 0.67 | I40: =IF($B$5=1,I10,IF($B$5=2,I20,I30)) -> 0.68 | J40: =IF($B$5=1,J10,IF($B$5=2,J20,J30)) -> 0.68 | K40: =IF($B$5=1,K10,IF($B$5=2,K20,K30)) -> 0.68 | L40: =IF($B$5=1,L10,IF($B$5=2,L20,L30)) -> 0.68 | ... X40: =IF($B$5=1,X10,IF($B$5=2,X20,X30)) -> 0.7
A41: Capex % of Revenue | E41: =IF($B$5=1,E11,IF($B$5=2,E21,E31)) -> 0.32 | F41: =IF($B$5=1,F11,IF($B$5=2,F21,F31)) -> 0.27 | G41: =IF($B$5=1,G11,IF($B$5=2,G21,G31)) -> 0.23 | H41: =IF($B$5=1,H11,IF($B$5=2,H21,H31)) -> 0.2 | I41: =IF($B$5=1,I11,IF($B$5=2,I21,I31)) -> 0.17 | J41: =IF($B$5=1,J11,IF($B$5=2,J21,J31)) -> 0.15 | K41: =IF($B$5=1,K11,IF($B$5=2,K21,K31)) -> 0.13 | L41: =IF($B$5=1,L11,IF($B$5=2,L21,L31)) -> 0.12 | ... X41: =IF($B$5=1,X11,IF($B$5=2,X21,X31)) -> 0.08
A42: ΔNW Cap % of ΔRevenue | E42: =IF($B$5=1,E12,IF($B$5=2,E22,E32)) -> 0.04 | F42: =IF($B$5=1,F12,IF($B$5=2,F22,F32)) -> 0.04 | G42: =IF($B$5=1,G12,IF($B$5=2,G22,G32)) -> 0.04 | H42: =IF($B$5=1,H12,IF($B$5=2,H22,H32)) -> 0.04 | I42: =IF($B$5=1,I12,IF($B$5=2,I22,I32)) -> 0.03 | J42: =IF($B$5=1,J12,IF($B$5=2,J22,J32)) -> 0.03 | K42: =IF($B$5=1,K12,IF($B$5=2,K22,K32)) -> 0.03 | L42: =IF($B$5=1,L12,IF($B$5=2,L22,L32)) -> 0.03 | ... X42: =IF($B$5=1,X12,IF($B$5=2,X22,X32)) -> 0.015
A43: Active Fleet (End of Period) | E43: =IF($B$5=1,E13,IF($B$5=2,E23,E33)) -> 11040 | F43: =IF($B$5=1,F13,IF($B$5=2,F23,F33)) -> 12696 | G43: =IF($B$5=1,G13,IF($B$5=2,G23,G33)) -> 14600 | H43: =IF($B$5=1,H13,IF($B$5=2,H23,H33)) -> 16060 | I43: =IF($B$5=1,I13,IF($B$5=2,I23,I33)) -> 17666 | J43: =IF($B$5=1,J13,IF($B$5=2,J23,J33)) -> 19433 | K43: =IF($B$5=1,K13,IF($B$5=2,K23,K33)) -> 20405 | L43: =IF($B$5=1,L13,IF($B$5=2,L23,L33)) -> 21425 | ... X43: =IF($B$5=1,X13,IF($B$5=2,X23,X33)) -> 27409
A44: SBC (% of Revenue) | E44: =IF($B$5=1,E14,IF($B$5=2,E24,E34)) -> 0.025 | F44: =IF($B$5=1,F14,IF($B$5=2,F24,F34)) -> 0.025 | G44: =IF($B$5=1,G14,IF($B$5=2,G24,G34)) -> 0.024 | H44: =IF($B$5=1,H14,IF($B$5=2,H24,H34)) -> 0.024 | I44: =IF($B$5=1,I14,IF($B$5=2,I24,I34)) -> 0.023 | J44: =IF($B$5=1,J14,IF($B$5=2,J24,J34)) -> 0.023 | K44: =IF($B$5=1,K14,IF($B$5=2,K24,K34)) -> 0.022 | L44: =IF($B$5=1,L14,IF($B$5=2,L24,L34)) -> 0.022 | ... X44: =IF($B$5=1,X14,IF($B$5=2,X24,X34)) -> 0.015
A45: Terminal Growth Rate | B45: =IF($B$5=1,B15,IF($B$5=2,B25,B35)) -> 0.03
A46: WACC | B46: =IF($B$5=1,B16,IF($B$5=2,B26,B36)) -> 0.063906891
...

Sheet Space DCF
A1: SpaceX – Space Segment DCF (Launch & Starship)
A2: S-1 Filed May 20, 2026 | 20-Year Explicit Forecast FY2026E–FY2045E | $ in Millions
A5: SCENARIO SELECTOR | B5: =Dashboard!B32 -> 2 | C5: =IF(B5=1,"◀ BEAR",IF(B5=2,"◀ BASE","◀ BULL")) -> ◀ BASE | D5: (1 = Bear | 2 = Base | 3 = Bull)
B6: FY2023A | C6: FY2024A | D6: FY2025A | E6: FY2026E | F6: FY2027E | G6: FY2028E | H6: FY2029E | I6: FY2030E | J6: FY2031E | K6: FY2032E | L6: FY2033E | M6: FY2034E | N6: FY2035E | O6: FY2036E | P6: FY2037E | Q6: FY2038E | R6: FY2039E | S6: FY2040E | T6: FY2041E | U6: FY2042E | V6: FY2043E | W6: FY2044E | X6: FY2045E
A8: BEAR CASE ASSUMPTIONS
A9: Revenue Growth % (YoY) | E9: 0.06 | F9: 0.08 | G9: 0.1 | H9: 0.12 | I9: 0.15 | J9: 0.15 | K9: 0.13 | L9: 0.12 | M9: 0.1 | N9: 0.08 | O9: 0.07 | P9: 0.06 | Q9: 0.05 | R9: 0.045 | S9: 0.04 | T9: 0.035 | U9: 0.03 | V9: 0.03 | W9: 0.028 | X9: 0.025
A10: EBITDA Margin % | E10: 0.1 | F10: 0.12 | G10: 0.15 | H10: 0.18 | I10: 0.22 | J10: 0.25 | K10: 0.27 | L10: 0.28 | M10: 0.29 | N10: 0.3 | O10: 0.31 | P10: 0.32 | Q10: 0.33 | R10: 0.34 | S10: 0.34 | T10: 0.35 | U10: 0.36 | V10: 0.37 | W10: 0.37 | X10: 0.38
A11: Capex % of Revenue | E11: 0.85 | F11: 0.75 | G11: 0.65 | H11: 0.55 | I11: 0.45 | J11: 0.38 | K11: 0.32 | L11: 0.28 | M11: 0.24 | N11: 0.22 | O11: 0.21 | P11: 0.2 | Q11: 0.19 | R11: 0.18 | S11: 0.17 | T11: 0.16 | U11: 0.15 | V11: 0.14 | W11: 0.13 | X11: 0.12
A12: ΔNW Cap % of ΔRevenue | E12: 0.06 | F12: 0.06 | G12: 0.05 | H12: 0.05 | I12: 0.05 | J12: 0.04 | K12: 0.04 | L12: 0.03 | M12: 0.03 | N12: 0.03 | O12: 0.03 | P12: 0.03 | Q12: 0.025 | R12: 0.025 | S12: 0.025 | T12: 0.025 | U12: 0.02 | V12: 0.02 | W12: 0.02 | X12: 0.02
A13: Total Falcon 9 Launches | E13: 180 | F13: 185 | G13: 185 | H13: 180 | I13: 165 | J13: 140 | K13: 110 | L13: 80 | M13: 55 | N13: 35 | O13: 22 | P13: 14 | Q13: 8 | R13: 5 | S13: 3 | T13: 0 | U13: 0 | V13: 0 | W13: 0 | X13: 0
A14: Total Starship Launches | E14: 5 | F14: 10 | G14: 25 | H14: 45 | I14: 70 | J14: 110 | K14: 155 | L14: 200 | M14: 250 | N14: 300 | O14: 340 | P14: 370 | Q14: 395 | R14: 415 | S14: 430 | T14: 440 | U14: 450 | V14: 460 | W14: 465 | X14: 470
A15: Starship D&A / Launch ($M) | E15: 2.5 | F15: 2.2 | G15: 2 | H15: 1.8 | I15: 1.5 | J15: 1.3 | K15: 1.15 | L15: 1.05 | M15: 0.95 | N15: 0.9 | O15: 0.85 | P15: 0.82 | Q15: 0.78 | R15: 0.75 | S15: 0.72 | T15: 0.7 | U15: 0.68 | V15: 0.67 | W15: 0.66 | X15: 0.65
A16: Terminal Growth Rate | B16: =WACC!D43 -> 0.02
A17: WACC | B17: =WACC!B43 -> 0.068984004
A19: BASE CASE ASSUMPTIONS
A20: Revenue Growth % (YoY) | E20: 0.1 | F20: 0.14 | G20: 0.18 | H20: 0.22 | I20: 0.26 | J20: 0.22 | K20: 0.18 | L20: 0.15 | M20: 0.13 | N20: 0.11 | O20: 0.1 | P20: 0.09 | Q20: 0.08 | R20: 0.07 | S20: 0.06 | T20: 0.05 | U20: 0.045 | V20: 0.04 | W20: 0.035 | X20: 0.03
A21: EBITDA Margin % | E21: 0.18 | F21: 0.18 | G21: 0.24 | H21: 0.3 | I21: 0.36 | J21: 0.41 | K21: 0.45 | L21: 0.47 | M21: 0.48 | N21: 0.49 | O21: 0.5 | P21: 0.51 | Q21: 0.52 | R21: 0.52 | S21: 0.53 | T21: 0.54 | U21: 0.54 | V21: 0.55 | W21: 0.55 | X21: 0.56
A22: Capex % of Revenue | E22: 0.75 | F22: 0.65 | G22: 0.55 | H22: 0.45 | I22: 0.36 | J22: 0.28 | K22: 0.22 | L22: 0.18 | M22: 0.15 | N22: 0.13 | O22: 0.125 | P22: 0.12 | Q22: 0.115 | R22: 0.11 | S22: 0.105 | T22: 0.1 | U22: 0.098 | V22: 0.095 | W22: 0.092 | X22: 0.09
A23: ΔNW Cap % of ΔRevenue | E23: 0.05 | F23: 0.05 | G23: 0.05 | H23: 0.04 | I23: 0.04 | J23: 0.04 | K23: 0.03 | L23: 0.03 | M23: 0.02 | N23: 0.02 | O23: 0.02 | P23: 0.02 | Q23: 0.02 | R23: 0.018 | S23: 0.018 | T23: 0.015 | U23: 0.015 | V23: 0.015 | W23: 0.015 | X23: 0.015
A24: Total Falcon 9 Launches | E24: 175 | F24: 180 | G24: 175 | H24: 160 | I24: 130 | J24: 100 | K24: 70 | L24: 45 | M24: 25 | N24: 15 | O24: 8 | P24: 5 | Q24: 3 | R24: 0 | S24: 0 | T24: 0 | U24: 0 | V24: 0 | W24: 0 | X24: 0
A25: Total Starship Launches | E25: 10 | F25: 24 | G25: 50 | H25: 80 | I25: 100 | J25: 150 | K25: 210 | L25: 280 | M25: 340 | N25: 400 | O25: 440 | P25: 470 | Q25: 490 | R25: 510 | S25: 520 | T25: 530 | U25: 540 | V25: 545 | W25: 550 | X25: 555
A26: Starship D&A / Launch ($M) | E26: 2 | F26: 1.8 | G26: 1.6 | H26: 1.4 | I26: 1.2 | J26: 1.1 | K26: 1 | L26: 0.9 | M26: 0.8 | N26: 0.76 | O26: 0.72 | P26: 0.68 | Q26: 0.64 | R26: 0.62 | S26: 0.6 | T26: 0.6 | U26: 0.6 | V26: 0.6 | W26: 0.6 | X26: 0.6
A27: Terminal Growth Rate | B27: =WACC!C43 -> 0.025
A28: WACC | B28: =WACC!B43 -> 0.068984004
A30: BULL CASE ASSUMPTIONS
A31: Revenue Growth % (YoY) | E31: 0.16 | F31: 0.22 | G31: 0.28 | H31: 0.32 | I31: 0.36 | J31: 0.3 | K31: 0.25 | L31: 0.2 | M31: 0.17 | N31: 0.14 | O31: 0.13 | P31: 0.12 | Q31: 0.11 | R31: 0.1 | S31: 0.09 | T31: 0.08 | U31: 0.07 | V31: 0.06 | W31: 0.05 | X31: 0.04
A32: EBITDA Margin % | E32: 0.18 | F32: 0.24 | G32: 0.32 | H32: 0.4 | I32: 0.46 | J32: 0.5 | K32: 0.52 | L32: 0.53 | M32: 0.54 | N32: 0.55 | O32: 0.56 | P32: 0.57 | Q32: 0.58 | R32: 0.59 | S32: 0.59 | T32: 0.6 | U32: 0.61 | V32: 0.61 | W32: 0.62 | X32: 0.62
A33: Capex % of Revenue | E33: 0.7 | F33: 0.6 | G33: 0.5 | H33: 0.4 | I33: 0.31 | J33: 0.24 | K33: 0.19 | L33: 0.16 | M33: 0.13 | N33: 0.11 | O33: 0.11 | P33: 0.105 | Q33: 0.1 | R33: 0.098 | S33: 0.095 | T33: 0.092 | U33: 0.09 | V33: 0.088 | W33: 0.085 | X33: 0.08
A34: ΔNW Cap % of ΔRevenue | E34: 0.04 | F34: 0.04 | G34: 0.04 | H34: 0.03 | I34: 0.03 | J34: 0.03 | K34: 0.02 | L34: 0.02 | M34: 0.02 | N34: 0.02 | O34: 0.02 | P34: 0.018 | Q34: 0.018 | R34: 0.015 | S34: 0.015 | T34: 0.015 | U34: 0.012 | V34: 0.012 | W34: 0.012 | X34: 0.012
A35: Total Falcon 9 Launches | E35: 170 | F35: 165 | G35: 150 | H35: 130 | I35: 100 | J35: 70 | K35: 45 | L35: 25 | M35: 12 | N35: 6 | O35: 3 | P35: 2 | Q35: 0 | R35: 0 | S35: 0 | T35: 0 | U35: 0 | V35: 0 | W35: 0 | X35: 0
A36: Total Starship Launches | E36: 15 | F36: 40 | G36: 80 | H36: 130 | I36: 180 | J36: 240 | K36: 310 | L36: 380 | M36: 450 | N36: 510 | O36: 560 | P36: 600 | Q36: 630 | R36: 650 | S36: 670 | T36: 685 | U36: 700 | V36: 710 | W36: 720 | X36: 730
A37: Starship D&A / Launch ($M) | E37: 1.8 | F37: 1.5 | G37: 1.2 | H37: 1 | I37: 0.85 | J37: 0.75 | K37: 0.68 | L37: 0.62 | M37: 0.57 | N37: 0.53 | O37: 0.5 | P37: 0.47 | Q37: 0.45 | R37: 0.43 | S37: 0.42 | T37: 0.41 | U37: 0.4 | V37: 0.39 | W37: 0.38 | X37: 0.37
A38: Terminal Growth Rate | B38: =WACC!E43 -> 0.03
A39: WACC | B39: =WACC!B43 -> 0.068984004
A41: SELECTED CASE ASSUMPTIONS (auto-updates with Scenario Selector)
A42: Revenue Growth % (YoY) | E42: =IF($B$5=1,E9,IF($B$5=2,E20,E31)) -> 0.1 | F42: =IF($B$5=1,F9,IF($B$5=2,F20,F31)) -> 0.14 | G42: =IF($B$5=1,G9,IF($B$5=2,G20,G31)) -> 0.18 | H42: =IF($B$5=1,H9,IF($B$5=2,H20,H31)) -> 0.22 | I42: =IF($B$5=1,I9,IF($B$5=2,I20,I31)) -> 0.26 | J42: =IF($B$5=1,J9,IF($B$5=2,J20,J31)) -> 0.22 | K42: =IF($B$5=1,K9,IF($B$5=2,K20,K31)) -> 0.18 | L42: =IF($B$5=1,L9,IF($B$5=2,L20,L31)) -> 0.15 | ... X42: =IF($B$5=1,X9,IF($B$5=2,X20,X31)) -> 0.03
A43: EBITDA Margin % | E43: =IF($B$5=1,E10,IF($B$5=2,E21,E32)) -> 0.18 | F43: =IF($B$5=1,F10,IF($B$5=2,F21,F32)) -> 0.18 | G43: =IF($B$5=1,G10,IF($B$5=2,G21,G32)) -> 0.24 | H43: =IF($B$5=1,H10,IF($B$5=2,H21,H32)) -> 0.3 | I43: =IF($B$5=1,I10,IF($B$5=2,I21,I32)) -> 0.36 | J43: =IF($B$5=1,J10,IF($B$5=2,J21,J32)) -> 0.41 | K43: =IF($B$5=1,K10,IF($B$5=2,K21,K32)) -> 0.45 | L43: =IF($B$5=1,L10,IF($B$5=2,L21,L32)) -> 0.47 | ... X43: =IF($B$5=1,X10,IF($B$5=2,X21,X32)) -> 0.56
A44: Capex % of Revenue | E44: =IF($B$5=1,E11,IF($B$5=2,E22,E33)) -> 0.75 | F44: =IF($B$5=1,F11,IF($B$5=2,F22,F33)) -> 0.65 | G44: =IF($B$5=1,G11,IF($B$5=2,G22,G33)) -> 0.55 | H44: =IF($B$5=1,H11,IF($B$5=2,H22,H33)) -> 0.45 | I44: =IF($B$5=1,I11,IF($B$5=2,I22,I33)) -> 0.36 | J44: =IF($B$5=1,J11,IF($B$5=2,J22,J33)) -> 0.28 | K44: =IF($B$5=1,K11,IF($B$5=2,K22,K33)) -> 0.22 | L44: =IF($B$5=1,L11,IF($B$5=2,L22,L33)) -> 0.18 | ... X44: =IF($B$5=1,X11,IF($B$5=2,X22,X33)) -> 0.09
A45: ΔNW Cap % of ΔRevenue | E45: =IF($B$5=1,E12,IF($B$5=2,E23,E34)) -> 0.05 | F45: =IF($B$5=1,F12,IF($B$5=2,F23,F34)) -> 0.05 | G45: =IF($B$5=1,G12,IF($B$5=2,G23,G34)) -> 0.05 | H45: =IF($B$5=1,H12,IF($B$5=2,H23,H34)) -> 0.04 | I45: =IF($B$5=1,I12,IF($B$5=2,I23,I34)) -> 0.04 | J45: =IF($B$5=1,J12,IF($B$5=2,J23,J34)) -> 0.04 | K45: =IF($B$5=1,K12,IF($B$5=2,K23,K34)) -> 0.03 | L45: =IF($B$5=1,L12,IF($B$5=2,L23,L34)) -> 0.03 | ... X45: =IF($B$5=1,X12,IF($B$5=2,X23,X34)) -> 0.015
A46: Total Falcon 9 Launches | E46: =IF($B$5=1,E13,IF($B$5=2,E24,E35)) -> 175 | F46: =IF($B$5=1,F13,IF($B$5=2,F24,F35)) -> 180 | G46: =IF($B$5=1,G13,IF($B$5=2,G24,G35)) -> 175 | H46: =IF($B$5=1,H13,IF($B$5=2,H24,H35)) -> 160 | I46: =IF($B$5=1,I13,IF($B$5=2,I24,I35)) -> 130 | J46: =IF($B$5=1,J13,IF($B$5=2,J24,J35)) -> 100 | K46: =IF($B$5=1,K13,IF($B$5=2,K24,K35)) -> 70 | L46: =IF($B$5=1,L13,IF($B$5=2,L24,L35)) -> 45 | ... X46: =IF($B$5=1,X13,IF($B$5=2,X24,X35)) -> 0
...

Sheet AI DCF
A1: SpaceX – AI Segment DCF (X / xAI / Grok)
A2: S-1 Filed May 20, 2026 | 20-Year Explicit Forecast FY2026E–FY2045E | $ in Millions
A3: ⚠ AI segment includes X (social/advertising), xAI (Grok/models), and compute infrastructure. Op losses reflect heavy investment phase; TV captures mature-state value.
A5: SCENARIO SELECTOR | B5: =Dashboard!B33 -> 2 | C5: =IF(B5=1,"◀ BEAR",IF(B5=2,"◀ BASE","◀ BULL")) -> ◀ BASE | D5: (1 = Bear | 2 = Base | 3 = Bull)
B6: FY2023A | C6: FY2024A | D6: FY2025A | E6: FY2026E | F6: FY2027E | G6: FY2028E | H6: FY2029E | I6: FY2030E | J6: FY2031E | K6: FY2032E | L6: FY2033E | M6: FY2034E | N6: FY2035E | O6: FY2036E | P6: FY2037E | Q6: FY2038E | R6: FY2039E | S6: FY2040E | T6: FY2041E | U6: FY2042E | V6: FY2043E | W6: FY2044E | X6: FY2045E
A8: BEAR CASE ASSUMPTIONS
A9: Revenue Growth % (YoY) | E9: 0.15 | F9: 0.2 | G9: 0.25 | H9: 0.28 | I9: 0.3 | J9: 0.28 | K9: 0.25 | L9: 0.22 | M9: 0.18 | N9: 0.15 | O9: 0.14 | P9: 0.13 | Q9: 0.12 | R9: 0.1 | S9: 0.09 | T9: 0.08 | U9: 0.07 | V9: 0.06 | W9: 0.05 | X9: 0.04
A10: EBITDA Margin % | E10: -0.3 | F10: -0.15 | G10: 0 | H10: 0.1 | I10: 0.18 | J10: 0.23 | K10: 0.27 | L10: 0.3 | M10: 0.32 | N10: 0.34 | O10: 0.36 | P10: 0.38 | Q10: 0.39 | R10: 0.4 | S10: 0.41 | T10: 0.42 | U10: 0.42 | V10: 0.43 | W10: 0.43 | X10: 0.44
A11: D&A % of Revenue | E11: 1.15 | F11: 1 | G11: 0.85 | H11: 0.72 | I11: 0.62 | J11: 0.54 | K11: 0.47 | L11: 0.42 | M11: 0.37 | N11: 0.33 | O11: 0.3 | P11: 0.28 | Q11: 0.26 | R11: 0.24 | S11: 0.23 | T11: 0.22 | U11: 0.21 | V11: 0.2 | W11: 0.19 | X11: 0.19
A12: Capex % of Revenue | E12: 3.6 | F12: 2.8 | G12: 2.1 | H12: 1.6 | I12: 1.2 | J12: 0.95 | K12: 0.78 | L12: 0.65 | M12: 0.55 | N12: 0.48 | O12: 0.44 | P12: 0.4 | Q12: 0.36 | R12: 0.33 | S12: 0.3 | T12: 0.27 | U12: 0.24 | V12: 0.22 | W12: 0.2 | X12: 0.18
A13: ΔNW Cap % of ΔRevenue | E13: 0.08 | F13: 0.07 | G13: 0.06 | H13: 0.06 | I13: 0.05 | J13: 0.05 | K13: 0.04 | L13: 0.04 | M13: 0.03 | N13: 0.03 | O13: 0.03 | P13: 0.03 | Q13: 0.025 | R13: 0.025 | S13: 0.025 | T13: 0.02 | U13: 0.02 | V13: 0.02 | W13: 0.02 | X13: 0.02
A14: Terminal Growth Rate | B14: =WACC!D44 -> 0.025
A15: WACC | B15: =WACC!B44 -> 0.10385358
A17: BASE CASE ASSUMPTIONS
A18: Revenue Growth % (YoY) | E18: 0.28 | F18: 0.38 | G18: 0.45 | H18: 0.48 | I18: 0.45 | J18: 0.38 | K18: 0.32 | L18: 0.27 | M18: 0.22 | N18: 0.18 | O18: 0.16 | P18: 0.15 | Q18: 0.13 | R18: 0.12 | S18: 0.1 | T18: 0.09 | U18: 0.08 | V18: 0.07 | W18: 0.06 | X18: 0.05
A19: EBITDA Margin % | E19: -0.15 | F19: 0.02 | G19: 0.12 | H19: 0.22 | I19: 0.3 | J19: 0.36 | K19: 0.4 | L19: 0.43 | M19: 0.45 | N19: 0.46 | O19: 0.48 | P19: 0.5 | Q19: 0.51 | R19: 0.52 | S19: 0.53 | T19: 0.54 | U19: 0.55 | V19: 0.56 | W19: 0.57 | X19: 0.58
A20: D&A % of Revenue | E20: 1.05 | F20: 0.9 | G20: 0.75 | H20: 0.62 | I20: 0.52 | J20: 0.44 | K20: 0.38 | L20: 0.33 | M20: 0.29 | N20: 0.26 | O20: 0.24 | P20: 0.22 | Q20: 0.2 | R20: 0.19 | S20: 0.18 | T20: 0.17 | U20: 0.16 | V20: 0.16 | W20: 0.15 | X20: 0.15
A21: Capex % of Revenue | E21: 3.2 | F21: 2.4 | G21: 1.8 | H21: 1.35 | I21: 1 | J21: 0.8 | K21: 0.65 | L21: 0.54 | M21: 0.46 | N21: 0.4 | O21: 0.36 | P21: 0.33 | Q21: 0.3 | R21: 0.27 | S21: 0.25 | T21: 0.22 | U21: 0.2 | V21: 0.18 | W21: 0.16 | X21: 0.15
A22: ΔNW Cap % of ΔRevenue | E22: 0.06 | F22: 0.06 | G22: 0.05 | H22: 0.05 | I22: 0.04 | J22: 0.04 | K22: 0.03 | L22: 0.03 | M22: 0.03 | N22: 0.02 | O22: 0.02 | P22: 0.02 | Q22: 0.02 | R22: 0.018 | S22: 0.018 | T22: 0.015 | U22: 0.015 | V22: 0.015 | W22: 0.015 | X22: 0.015
A23: Terminal Growth Rate | B23: =WACC!C44 -> 0.035
A24: WACC | B24: =WACC!B44 -> 0.10385358
A26: BULL CASE ASSUMPTIONS
A27: Revenue Growth % (YoY) | E27: 0.45 | F27: 0.6 | G27: 0.7 | H27: 0.7 | I27: 0.6 | J27: 0.5 | K27: 0.42 | L27: 0.35 | M27: 0.28 | N27: 0.22 | O27: 0.2 | P27: 0.18 | Q27: 0.16 | R27: 0.14 | S27: 0.12 | T27: 0.11 | U27: 0.1 | V27: 0.09 | W27: 0.07 | X27: 0.06
A28: EBITDA Margin % | E28: -0.1 | F28: -0.05 | G28: 0.05 | H28: 0.12 | I28: 0.2 | J28: 0.28 | K28: 0.35 | L28: 0.42 | M28: 0.48 | N28: 0.55 | O28: 0.57 | P28: 0.59 | Q28: 0.6 | R28: 0.61 | S28: 0.62 | T28: 0.63 | U28: 0.64 | V28: 0.65 | W28: 0.65 | X28: 0.66
A29: D&A % of Revenue | E29: 0.95 | F29: 0.78 | G29: 0.63 | H29: 0.5 | I29: 0.4 | J29: 0.33 | K29: 0.28 | L29: 0.24 | M29: 0.21 | N29: 0.19 | O29: 0.17 | P29: 0.16 | Q29: 0.15 | R29: 0.14 | S29: 0.13 | T29: 0.12 | U29: 0.12 | V29: 0.11 | W29: 0.11 | X29: 0.1
A30: Capex % of Revenue | E30: 2.9 | F30: 2.1 | G30: 1.55 | H30: 1.15 | I30: 0.85 | J30: 0.68 | K30: 0.55 | L30: 0.46 | M30: 0.39 | N30: 0.34 | O30: 0.3 | P30: 0.27 | Q30: 0.25 | R30: 0.22 | S30: 0.2 | T30: 0.18 | U30: 0.16 | V30: 0.15 | W30: 0.14 | X30: 0.13
A31: ΔNW Cap % of ΔRevenue | E31: 0.05 | F31: 0.05 | G31: 0.04 | H31: 0.04 | I31: 0.03 | J31: 0.03 | K31: 0.03 | L31: 0.02 | M31: 0.02 | N31: 0.02 | O31: 0.02 | P31: 0.018 | Q31: 0.018 | R31: 0.015 | S31: 0.015 | T31: 0.015 | U31: 0.012 | V31: 0.012 | W31: 0.012 | X31: 0.012
A32: Terminal Growth Rate | B32: =WACC!E44 -> 0.04
A33: WACC | B33: =WACC!B44 -> 0.10385358
A35: SELECTED CASE ASSUMPTIONS
A36: Revenue Growth % (YoY) | E36: =IF($B$5=1,E9,IF($B$5=2,E18,E27)) -> 0.28 | F36: =IF($B$5=1,F9,IF($B$5=2,F18,F27)) -> 0.38 | G36: =IF($B$5=1,G9,IF($B$5=2,G18,G27)) -> 0.45 | H36: =IF($B$5=1,H9,IF($B$5=2,H18,H27)) -> 0.48 | I36: =IF($B$5=1,I9,IF($B$5=2,I18,I27)) -> 0.45 | J36: =IF($B$5=1,J9,IF($B$5=2,J18,J27)) -> 0.38 | K36: =IF($B$5=1,K9,IF($B$5=2,K18,K27)) -> 0.32 | L36: =IF($B$5=1,L9,IF($B$5=2,L18,L27)) -> 0.27 | ... X36: =IF($B$5=1,X9,IF($B$5=2,X18,X27)) -> 0.05
A37: EBITDA Margin % | E37: =IF($B$5=1,E10,IF($B$5=2,E19,E28)) -> -0.15 | F37: =IF($B$5=1,F10,IF($B$5=2,F19,F28)) -> 0.02 | G37: =IF($B$5=1,G10,IF($B$5=2,G19,G28)) -> 0.12 | H37: =IF($B$5=1,H10,IF($B$5=2,H19,H28)) -> 0.22 | I37: =IF($B$5=1,I10,IF($B$5=2,I19,I28)) -> 0.3 | J37: =IF($B$5=1,J10,IF($B$5=2,J19,J28)) -> 0.36 | K37: =IF($B$5=1,K10,IF($B$5=2,K19,K28)) -> 0.4 | L37: =IF($B$5=1,L10,IF($B$5=2,L19,L28)) -> 0.43 | ... X37: =IF($B$5=1,X10,IF($B$5=2,X19,X28)) -> 0.58
A38: D&A % of Revenue | E38: =IF($B$5=1,E11,IF($B$5=2,E20,E29)) -> 1.05 | F38: =IF($B$5=1,F11,IF($B$5=2,F20,F29)) -> 0.9 | G38: =IF($B$5=1,G11,IF($B$5=2,G20,G29)) -> 0.75 | H38: =IF($B$5=1,H11,IF($B$5=2,H20,H29)) -> 0.62 | I38: =IF($B$5=1,I11,IF($B$5=2,I20,I29)) -> 0.52 | J38: =IF($B$5=1,J11,IF($B$5=2,J20,J29)) -> 0.44 | K38: =IF($B$5=1,K11,IF($B$5=2,K20,K29)) -> 0.38 | L38: =IF($B$5=1,L11,IF($B$5=2,L20,L29)) -> 0.33 | ... X38: =IF($B$5=1,X11,IF($B$5=2,X20,X29)) -> 0.15
A39: Capex % of Revenue | E39: =IF($B$5=1,E12,IF($B$5=2,E21,E30)) -> 3.2 | F39: =IF($B$5=1,F12,IF($B$5=2,F21,F30)) -> 2.4 | G39: =IF($B$5=1,G12,IF($B$5=2,G21,G30)) -> 1.8 | H39: =IF($B$5=1,H12,IF($B$5=2,H21,H30)) -> 1.35 | I39: =IF($B$5=1,I12,IF($B$5=2,I21,I30)) -> 1 | J39: =IF($B$5=1,J12,IF($B$5=2,J21,J30)) -> 0.8 | K39: =IF($B$5=1,K12,IF($B$5=2,K21,K30)) -> 0.65 | L39: =IF($B$5=1,L12,IF($B$5=2,L21,L30)) -> 0.54 | ... X39: =IF($B$5=1,X12,IF($B$5=2,X21,X30)) -> 0.15
A40: ΔNW Cap % of ΔRevenue | E40: =IF($B$5=1,E13,IF($B$5=2,E22,E31)) -> 0.06 | F40: =IF($B$5=1,F13,IF($B$5=2,F22,F31)) -> 0.06 | G40: =IF($B$5=1,G13,IF($B$5=2,G22,G31)) -> 0.05 | H40: =IF($B$5=1,H13,IF($B$5=2,H22,H31)) -> 0.05 | I40: =IF($B$5=1,I13,IF($B$5=2,I22,I31)) -> 0.04 | J40: =IF($B$5=1,J13,IF($B$5=2,J22,J31)) -> 0.04 | K40: =IF($B$5=1,K13,IF($B$5=2,K22,K31)) -> 0.03 | L40: =IF($B$5=1,L13,IF($B$5=2,L22,L31)) -> 0.03 | ... X40: =IF($B$5=1,X13,IF($B$5=2,X22,X31)) -> 0.015
A41: Terminal Growth Rate | B41: =IF($B$5=1,B14,IF($B$5=2,B23,B32)) -> 0.035
A42: WACC | B42: =IF($B$5=1,B15,IF($B$5=2,B24,B33)) -> 0.10385358
A43: Blended WACC (Sensitivity Center) | B43: =AVERAGE(E77:X77) -> 0.13727693
A45: AI SEGMENT – INCOME STATEMENT & FREE CASH FLOW ($M)
A46: Revenue | B46: =Actuals!B10 -> 2961 | C46: =Actuals!C10 -> 2620 | D46: =Actuals!D10 -> 3201 | E46: =D46*(1+E36) -> 4097.28 | F46: =E46*(1+F36) -> 5654.2464 | G46: =F46*(1+G36) -> 8198.6573 | H46: =G46*(1+H36) -> 12134.013 | I46: =H46*(1+I36) -> 17594.319 | J46: =I46*(1+J36) -> 24280.16 | K46: =J46*(1+K36) -> 32049.811 | L46: =K46*(1+L36) -> 40703.259 | ... X46: =W46*(1+X36) -> 152561.59
...

Sheet WACC
A1: SpaceX – Weighted Average Cost of Capital
A2: May 2026 | Sum-of-the-Parts Segment WACCs | $M
A4: MACRO INPUTS
A6: Item | B6: Value | G6: Note
A7: Risk-Free Rate (10Y US Treasury) | B7: 0.0435 | G7: US Treasury, Jun 2026
A8: Equity Risk Premium | B8: 0.055 | G8: Damodaran Jan 2026 (US ERP)
A9: Tax Rate | B9: 0.21 | G9: US statutory; SpaceX has large NOL carryforwards
A10: Specific Risk Premium (Size / Illiquidity) | B10: 0.01 | G10: Pre-IPO illiquidity + size/execution risk; 2–3% typical for late-stage private
A12: UNLEVERED BETA BY SEGMENT (Comp-Driven – mature-stage tier median)
A14: Segment | B14: Selected Unlevered β | G14: Rationale
A15: Connectivity (Starlink) | B15: =IF(N('Conn Comps'!X54)>0,'Conn Comps'!X54,0.85) -> 0.20833333 | G15: Mature Wireless comp median unlevered β (fallback 0.85)
A16: Space (Launch) | B16: =IF(N('Space Comps'!X35)>0,'Space Comps'!X35,1.1) -> 0.26644722 | G16: Big-5 Defense comp median unlevered β (fallback 1.10)
A17: AI (X + xAI) | B17: =IF(N('AI Comps'!X43)>0,'AI Comps'!X43,1.35) -> 0.90384475 | G17: Social Media comp median unlevered β (fallback 1.35); excludes high-β neoclouds
A19: COST OF EQUITY BY SEGMENT
B21: Connectivity | C21: Space | D21: AI | G21: Formula
A22: Target D/E (post-IPO est.) | B22: 0.3 | C22: 0.45 | D22: 0.25 | G22: Based on Dec 2025 debt / est. post-IPO market cap by seg
A23: Relevered β | B23: =B15*(1+(1-$B$9)*B22) -> 0.25770833 | C23: =B16*(1+(1-$B$9)*C22) -> 0.3611692 | D23: =B17*(1+(1-$B$9)*D22) -> 1.0823541 | G23: βL = βU × (1 + (1-t) × D/E)
A24: Cost of Equity (CAPM) | B24: =$B$7+B23*$B$8+$B$10 -> 0.067673958 | C24: =$B$7+C23*$B$8+$B$10 -> 0.073364306 | D24: =$B$7+D23*$B$8+$B$10 -> 0.11302947 | G24: Ke = Rf + βL × ERP + SRP
A26: COST OF DEBT
B28: Connectivity | C28: Space | D28: AI | G28: Note
A29: Pre-Tax Cost of Debt | B29: 0.065 | C29: 0.075 | D29: 0.085 | G29: Based on SpaceX credit facility + X debt yields, Jun 2026
A30: After-Tax Cost of Debt | B30: =B29*(1-$B$9) -> 0.05135 | C30: =C29*(1-$B$9) -> 0.05925 | D30: =D29*(1-$B$9) -> 0.06715 | G30: Kd × (1-t)
A32: WACC CALCULATION
B34: Connectivity | C34: Space | D34: AI
A35: Equity Weight | B35: =1/(1+B22) -> 0.76923077 | C35: =1/(1+C22) -> 0.68965517 | D35: =1/(1+D22) -> 0.8 | G35: E/(E+D) = 1/(1+D/E)
A36: Debt Weight | B36: =B22/(1+B22) -> 0.23076923 | C36: =C22/(1+C22) -> 0.31034483 | D36: =D22/(1+D22) -> 0.2 | G36: D/(E+D) = (D/E)/(1+D/E)
A37: WACC | B37: =B24*B35+B30*B36 -> 0.063906891 | C37: =C24*C35+C30*C36 -> 0.068984004 | D37: =D24*D35+D30*D36 -> 0.10385358 | G37: WACC = Ke×We + Kd×Wd
A39: WACC SUMMARY (referenced by DCF sheets)
A41: Segment | B41: WACC | C41: Tg (Base) | D41: Tg (Bear) | E41: Tg (Bull)
A42: Connectivity | B42: =B37 -> 0.063906891 | C42: 0.03 | D42: 0.025 | E42: 0.035
A43: Space | B43: =C37 -> 0.068984004 | C43: 0.025 | D43: 0.02 | E43: 0.03
A44: AI | B44: =D37 -> 0.10385358 | C44: 0.035 | D44: 0.025 | E44: 0.04
A46: TIME-WEIGHTED WACC (per-year, used in primary DCF valuation)
A48: Segment | B48: Year 1 WACC | C48: Year 20 WACC | D48: Static WACC | E48: Yr 1 Δ | G48: Note
A49: Connectivity | B49: ='Conn DCF'!E77 -> 0.076352699 | C49: ='Conn DCF'!X77 -> 0.068413495 | D49: =B42 -> 0.063906891 | E49: =B49-D49 -> 0.012445808 | G49: Time-weighted beta glides from Tier 1 (satellite) → Tier 3 (mature wireless) over 20 years
A50: Space | B50: ='Space DCF'!E85 -> 0.12008989 | C50: ='Space DCF'!X85 -> 0.081760475 | D50: =B43 -> 0.068984004 | E50: =B50-D50 -> 0.051105884 | G50: Glides from Tier 1 (NewSpace) → Tier 2 (Big-5 Defense) over 20 years
A51: AI | B51: ='AI DCF'!E77 -> 0.15398861 | C51: ='AI DCF'!X77 -> 0.12056526 | D51: =B44 -> 0.10385358 | E51: =B51-D51 -> 0.050135028 | G51: Glides from Tier 1 (GPU Neoclouds) → Tier 3 (Social Media); Tier 2 (Infra Hosting) excluded (β=3.1 unreliable)

Sheet Conn Comps
A1: CONNECTIVITY – COMPARABLE COMPANY ANALYSIS
A2: Comparable Public Companies by Maturity & Industry | Satellite Broadband + Telecom Infrastructure | $ in Millions
A3: Current-stage anchor = Satellite / LEO Broadband • Mature-stage anchor = Telecom Infrastructure. Input cells (blue) to be populated from terminal (CapIQ/Bloomberg).
A5: Name | B5: Ticker | C5: Mkt Cap | D5: Enterprise | E5: LTM | F5: Gross | G5: EBITDA | H5: Capex % | I5: 3-Yr Ann. | J5: TEV / | K5: TEV / | M5: # Subs | N5: ARPU | P5: Levered | Q5: Debt | R5: % Debt | S5: Preferred | T5: % Pref | U5: Equity | V5: % Equity | W5: Tax | X5: Unlevered
C6: ($M) | D6: Value ($M) | E6: Revenue ($M) | F6: Margin | G6: Margin | H6: Revenue | I6: Rev Growth | J6: Revenue | K6: EBITDA | M6: (M) | N6: ($) | P6: Beta | Q6: ($M) | S6: Stock ($M) | U6: Value ($M) | W6: Rate | X6: Beta
A8: TIER 1 – PUBLIC SATELLITE OPERATORS (current-stage anchor)
A9: Iridium Communications | B9: NasdaqGS:IRDM | C9: 3200 | D9: 4600 | E9: 830 | F9: 0.7195 | G9: 0.62 | H9: 0.045 | I9: 0.05 | J9: =IFERROR(IF(D9=0,"NM",D9/E9),"NM") -> 5.5421687 | K9: =IF(OR(G9<=0,E9=0,D9=0),"NM",IF(D9/(E9*G9)>100,"NM",D9/(E9*G9))) -> 8.9389817 | M9: 2.555 | N9: 27 | P9: 0.6 | Q9: 1810 | R9: =IFERROR(Q9/(Q9+S9+U9),"") -> 0.25138889 | S9: 0 | T9: =IFERROR(S9/($Q9+$S9+$U9),"") -> 0 | U9: 5390 | V9: =IFERROR(U9/(Q9+S9+U9),"") -> 0.74861111 | W9: 0.21 | X9: =IFERROR(P9/(1+(Q9/U9)*(1-W9)+S9/U9),"") -> 0.4742005
A10: EchoStar Corporation | B10: NasdaqGS:SATS | C10: 36100 | D10: 61430 | E10: 14800 | F10: 0.37 | G10: 0.37 | H10: 0.115 | I10: 0.11 | J10: =IFERROR(IF(D10=0,"NM",D10/E10),"NM") -> 4.1506757 | K10: =IF(OR(G10<=0,E10=0,D10=0),"NM",IF(D10/(E10*G10)>100,"NM",D10/(E10*G10))) -> 11.218042 | M10: 29.2 | N10: 40 | P10: 0.96 | Q10: 29240 | R10: =IFERROR(Q10/(Q10+S10+U10),"") -> 0.47130883 | S10: 0 | T10: =IFERROR(S10/($Q10+$S10+$U10),"") -> 0 | U10: 32800 | V10: =IFERROR(U10/(Q10+S10+U10),"") -> 0.52869117 | W10: 0.21 | X10: =IFERROR(P10/(1+(Q10/U10)*(1-W10)+S10/U10),"") -> 0.56329562
A11: Globalstar, Inc. | B11: NasdaqGS:GSAT | C11: 3000 | D11: 3500 | E11: 250 | F11: 0.6381 | G11: 0.4 | H11: 0.8 | I11: 0.1 | J11: =IFERROR(IF(D11=0,"NM",D11/E11),"NM") -> 14 | K11: =IF(OR(G11<=0,E11=0,D11=0),"NM",IF(D11/(E11*G11)>100,"NM",D11/(E11*G11))) -> 35 | M11: NM | N11: NM | P11: 2.6 | Q11: 546 | R11: =IFERROR(Q11/(Q11+S11+U11),"") -> 0.044953071 | S11: 0 | T11: =IFERROR(S11/($Q11+$S11+$U11),"") -> 0 | U11: 11600 | V11: =IFERROR(U11/(Q11+S11+U11),"") -> 0.95504693 | W11: 0.21 | X11: =IFERROR(P11/(1+(Q11/U11)*(1-W11)+S11/U11),"") -> 2.5067864
A12: AST SpaceMobile, Inc. | B12: NasdaqGS:ASTS | C12: 15600 | D12: 15100 | E12: 71 | F12: 0.4482 | G12: -2 | H12: 5 | I12: 0.15 | J12: =IFERROR(IF(D12=0,"NM",D12/E12),"NM") -> 212.67606 | K12: =IF(OR(G12<=0,E12=0,D12=0),"NM",IF(D12/(E12*G12)>100,"NM",D12/(E12*G12))) -> NM | M12: NM | N12: NM | P12: 2.6 | Q12: 2990 | R12: =IFERROR(Q12/(Q12+S12+U12),"") -> 0.096607431 | S12: 0 | T12: =IFERROR(S12/($Q12+$S12+$U12),"") -> 0 | U12: 27960 | V12: =IFERROR(U12/(Q12+S12+U12),"") -> 0.90339257 | W12: 0.21 | X12: =IFERROR(P12/(1+(Q12/U12)*(1-W12)+S12/U12),"") -> 2.3974593
A13: Viasat, Inc. | B13: NasdaqGS:VSAT | C13: 6640 | D13: 12000 | E13: 4500 | F13: 0.332 | G13: 0.3 | H13: 0.199 | I13: 0.08 | J13: =IFERROR(IF(D13=0,"NM",D13/E13),"NM") -> 2.6666667 | K13: =IF(OR(G13<=0,E13=0,D13=0),"NM",IF(D13/(E13*G13)>100,"NM",D13/(E13*G13))) -> 8.8888889 | M13: NM | N13: NM | P13: 1.37 | Q13: 7080 | R13: =IFERROR(Q13/(Q13+S13+U13),"") -> 0.43839009 | S13: 0 | T13: =IFERROR(S13/($Q13+$S13+$U13),"") -> 0 | U13: 9070 | V13: =IFERROR(U13/(Q13+S13+U13),"") -> 0.56160991 | W13: 0.21 | X13: =IFERROR(P13/(1+(Q13/U13)*(1-W13)+S13/U13),"") -> 0.84742075
A14: SES S.A. | B14: ENXTPA:SESG | C14: 6300 | D14: 12560 | E14: 2850 | F14: 0.6 | G14: 0.43 | H14: 0.5 | I14: 0.05 | J14: =IFERROR(IF(D14=0,"NM",D14/E14),"NM") -> 4.4070175 | K14: =IF(OR(G14<=0,E14=0,D14=0),"NM",IF(D14/(E14*G14)>100,"NM",D14/(E14*G14))) -> 10.248878 | M14: NM | N14: NM | P14: 0.51 | Q14: 3400 | R14: =IFERROR(Q14/(Q14+S14+U14),"") -> 0.57627119 | S14: 0 | T14: =IFERROR(S14/($Q14+$S14+$U14),"") -> 0 | U14: 2500 | V14: =IFERROR(U14/(Q14+S14+U14),"") -> 0.42372881 | W14: 0.21 | X14: =IFERROR(P14/(1+(Q14/U14)*(1-W14)+S14/U14),"") -> 0.24585422
A15: Eutelsat Communications | B15: ENXTPA:ETL | C15: 3840 | D15: 4810 | E15: 1230 | F15: 0.5 | G15: 0.3 | H15: 0.45 | I15: 0.08 | J15: =IFERROR(IF(D15=0,"NM",D15/E15),"NM") -> 3.9105691 | K15: =IF(OR(G15<=0,E15=0,D15=0),"NM",IF(D15/(E15*G15)>100,"NM",D15/(E15*G15))) -> 13.03523 | M15: NM | N15: NM | P15: 0.9 | Q15: 7300 | R15: =IFERROR(Q15/(Q15+S15+U15),"") -> 0.72277228 | S15: 0 | T15: =IFERROR(S15/($Q15+$S15+$U15),"") -> 0 | U15: 2800 | V15: =IFERROR(U15/(Q15+S15+U15),"") -> 0.27722772 | W15: 0.25 | X15: =IFERROR(P15/(1+(Q15/U15)*(1-W15)+S15/U15),"") -> 0.30453172
A16: Telesat Corporation | B16: NasdaqGS:TSAT | C16: 2460 | D16: 5500 | E16: 279 | F16: 0.65 | G16: 0.65 | H16: 0.35 | I16: 0.05 | J16: =IFERROR(IF(D16=0,"NM",D16/E16),"NM") -> 19.713262 | K16: =IF(OR(G16<=0,E16=0,D16=0),"NM",IF(D16/(E16*G16)>100,"NM",D16/(E16*G16))) -> 30.328095 | M16: NM | N16: NM | P16: 2 | Q16: 4200 | R16: =IFERROR(Q16/(Q16+S16+U16),"") -> 0.87318087 | S16: 0 | T16: =IFERROR(S16/($Q16+$S16+$U16),"") -> 0 | U16: 610 | V16: =IFERROR(U16/(Q16+S16+U16),"") -> 0.12681913 | W16: 0.265 | X16: =IFERROR(P16/(1+(Q16/U16)*(1-W16)+S16/U16),"") -> 0.3299973
A18: Min: | C18: =IFERROR(MIN(C9:C16),"") -> 2460 | D18: =IFERROR(MIN(D9:D16),"") -> 3500 | E18: =IFERROR(MIN(E9:E16),"") -> 71 | F18: =IFERROR(MIN(F9:F16),"") -> 0.332 | G18: =IFERROR(MIN(G9:G16),"") -> -2 | H18: =IFERROR(MIN(H9:H16),"") -> 0.045 | I18: =IFERROR(MIN(I9:I16),"") -> 0.05 | J18: =IFERROR(_xlfn.AGGREGATE(5,6,J9:J16),"") -> 2.6666667 | K18: =IFERROR(MIN(K9:K16),"") -> 8.8888889 | M18: =IFERROR(IF(COUNTA(M9:M16)=0,"",MIN(M9:M16)),"") -> 2.555 | N18: =IFERROR(IF(COUNTA(N9:N16)=0,"",MIN(N9:N16)),"") -> 27 | P18: =IFERROR(MIN(P9:P16),"") -> 0.51 | Q18: =IFERROR(MIN(Q9:Q16),"") -> 546 | R18: =IFERROR(MIN(R9:R16),"") -> 0.044953071 | S18: =IFERROR(MIN(S9:S16),"") -> 0 | T18: =IFERROR(MIN(T9:T16),"") -> 0 | U18: =IFERROR(MIN(U9:U16),"") -> 610 | V18: =IFERROR(MIN(V9:V16),"") -> 0.12681913 | W18: =IFERROR(MIN(W9:W16),"") -> 0.21 | X18: =IFERROR(MIN(X9:X16),"") -> 0.24585422
A19: 25th Pctl: | C19: =IFERROR(QUARTILE(C9:C16,1),"") -> 3150 | D19: =IFERROR(QUARTILE(D9:D16,1),"") -> 4757.5 | E19: =IFERROR(QUARTILE(E9:E16,1),"") -> 271.75 | F19: =IFERROR(QUARTILE(F9:F16,1),"") -> 0.42865 | G19: =IFERROR(QUARTILE(G9:G16,1),"") -> 0.3 | H19: =IFERROR(QUARTILE(H9:H16,1),"") -> 0.178 | I19: =IFERROR(QUARTILE(I9:I16,1),"") -> 0.05 | J19: =IFERROR(QUARTILE(J9:J16,1),"") -> 4.090649 | K19: =QUARTILE((K9,K10,K11,K13,K14,K15,K16),1) -> 9.5939299 | M19: =IFERROR(QUARTILE(M9:M16,1),"") -> 9.21625 | N19: =IFERROR(QUARTILE(N9:N16,1),"") -> 30.25 | P19: =IFERROR(QUARTILE(P9:P16,1),"") -> 0.825 | Q19: =IFERROR(QUARTILE(Q9:Q16,1),"") -> 2695 | R19: =IFERROR(QUARTILE(R9:R16,1),"") -> 0.21269352 | S19: =IFERROR(QUARTILE(S9:S16,1),"") -> 0 | T19: =IFERROR(QUARTILE(T9:T16,1),"") -> 0 | U19: =IFERROR(QUARTILE(U9:U16,1),"") -> 2725 | V19: =IFERROR(QUARTILE(V9:V16,1),"") -> 0.38710354 | W19: =IFERROR(QUARTILE(W9:W16,1),"") -> 0.21 | X19: =IFERROR(QUARTILE(X9:X16,1),"") -> 0.3236309
A20: Median: | C20: =IFERROR(MEDIAN(C9:C16),"") -> 5070 | D20: =IFERROR(MEDIAN(D9:D16),"") -> 8750 | E20: =IFERROR(MEDIAN(E9:E16),"") -> 1030 | F20: =IFERROR(MEDIAN(F9:F16),"") -> 0.55 | G20: =IFERROR(MEDIAN(G9:G16),"") -> 0.385 | H20: =IFERROR(MEDIAN(H9:H16),"") -> 0.4 | I20: =IFERROR(MEDIAN(I9:I16),"") -> 0.08 | J20: =IFERROR(QUARTILE(J9:J16,2),"") -> 4.9745931 | K20: =QUARTILE((K9,K10,K11,K13,K14,K15,K16),2) -> 11.218042 | M20: =IFERROR(MEDIAN(M9:M16),"") -> 15.8775 | N20: =IFERROR(MEDIAN(N9:N16),"") -> 33.5 | P20: =IFERROR(MEDIAN(P9:P16),"") -> 1.165 | Q20: =IFERROR(MEDIAN(Q9:Q16),"") -> 3800 | R20: =IFERROR(MEDIAN(R9:R16),"") -> 0.45484946 | S20: =IFERROR(MEDIAN(S9:S16),"") -> 0 | T20: =IFERROR(MEDIAN(T9:T16),"") -> 0 | U20: =IFERROR(MEDIAN(U9:U16),"") -> 7230 | V20: =IFERROR(MEDIAN(V9:V16),"") -> 0.54515054 | W20: =IFERROR(MEDIAN(W9:W16),"") -> 0.21 | X20: =IFERROR(MEDIAN(X9:X16),"") -> 0.51874806
A21: Mean: | C21: =IFERROR(AVERAGE(C9:C16),"") -> 9642.5 | D21: =IFERROR(AVERAGE(D9:D16),"") -> 14937.5 | E21: =IFERROR(AVERAGE(E9:E16),"") -> 3101.25 | F21: =IFERROR(AVERAGE(F9:F16),"") -> 0.532225 | G21: =IFERROR(AVERAGE(G9:G16),"") -> 0.13375 | H21: =IFERROR(AVERAGE(H9:H16),"") -> 0.932375 | I21: =IFERROR(AVERAGE(I9:I16),"") -> 0.08375 | J21: =IFERROR(_xlfn.AGGREGATE(1,6,J9:J16),"") -> 33.383302 | K21: =IFERROR(AVERAGE(K9:K16),"") -> 16.808302 | M21: =IFERROR(AVERAGE(M9:M16),"") -> 15.8775 | N21: =IFERROR(AVERAGE(N9:N16),"") -> 33.5 | P21: =IFERROR(AVERAGE(P9:P16),"") -> 1.4425 | Q21: =IFERROR(AVERAGE(Q9:Q16),"") -> 7070.75 | R21: =IFERROR(AVERAGE(R9:R16),"") -> 0.43435908 | S21: =IFERROR(AVERAGE(S9:S16),"") -> 0 | T21: =IFERROR(AVERAGE(T9:T16),"") -> 0 | U21: =IFERROR(AVERAGE(U9:U16),"") -> 11591.25 | V21: =IFERROR(AVERAGE(V9:V16),"") -> 0.56564092 | W21: =IFERROR(AVERAGE(W9:W16),"") -> 0.221875 | X21: =IFERROR(AVERAGE(X9:X16),"") -> 0.95869323
A22: 75th Pctl: | C22: =IFERROR(QUARTILE(C9:C16,3),"") -> 8880 | D22: =IFERROR(QUARTILE(D9:D16,3),"") -> 13195 | E22: =IFERROR(QUARTILE(E9:E16,3),"") -> 3262.5 | F22: =IFERROR(QUARTILE(F9:F16,3),"") -> 0.641075 | G22: =IFERROR(QUARTILE(G9:G16,3),"") -> 0.4775 | H22: =IFERROR(QUARTILE(H9:H16,3),"") -> 0.575 | I22: =IFERROR(QUARTILE(I9:I16,3),"") -> 0.1025 | J22: =IFERROR(QUARTILE(J9:J16,3),"") -> 15.428315 | K22: =QUARTILE((K9,K10,K11,K13,K14,K15,K16),3) -> 21.681663 | M22: =IFERROR(QUARTILE(M9:M16,3),"") -> 22.53875 | N22: =IFERROR(QUARTILE(N9:N16,3),"") -> 36.75 | P22: =IFERROR(QUARTILE(P9:P16,3),"") -> 2.15 | Q22: =IFERROR(QUARTILE(Q9:Q16,3),"") -> 7135 | R22: =IFERROR(QUARTILE(R9:R16,3),"") -> 0.61289646 | S22: =IFERROR(QUARTILE(S9:S16,3),"") -> 0 | T22: =IFERROR(QUARTILE(T9:T16,3),"") -> 0 | U22: =IFERROR(QUARTILE(U9:U16,3),"") -> 15690 | V22: =IFERROR(QUARTILE(V9:V16,3),"") -> 0.78730648 | W22: =IFERROR(QUARTILE(W9:W16,3),"") -> 0.22 | X22: =IFERROR(QUARTILE(X9:X16,3),"") -> 1.2349304
A23: Max: | C23: =IFERROR(MAX(C9:C16),"") -> 36100 | D23: =IFERROR(MAX(D9:D16),"") -> 61430 | E23: =IFERROR(MAX(E9:E16),"") -> 14800 | F23: =IFERROR(MAX(F9:F16),"") -> 0.7195 | G23: =IFERROR(MAX(G9:G16),"") -> 0.65 | H23: =IFERROR(MAX(H9:H16),"") -> 5 | I23: =IFERROR(MAX(I9:I16),"") -> 0.15 | J23: =IFERROR(_xlfn.AGGREGATE(4,6,J9:J16),"") -> 212.67606 | K23: =IFERROR(MAX(K9:K16),"") -> 35 | M23: =IFERROR(IF(COUNTA(M9:M16)=0,"",MAX(M9:M16)),"") -> 29.2 | N23: =IFERROR(IF(COUNTA(N9:N16)=0,"",MAX(N9:N16)),"") -> 40 | P23: =IFERROR(MAX(P9:P16),"") -> 2.6 | Q23: =IFERROR(MAX(Q9:Q16),"") -> 29240 | R23: =IFERROR(MAX(R9:R16),"") -> 0.87318087 | S23: =IFERROR(MAX(S9:S16),"") -> 0 | T23: =IFERROR(MAX(T9:T16),"") -> 0 | U23: =IFERROR(MAX(U9:U16),"") -> 32800 | V23: =IFERROR(MAX(V9:V16),"") -> 0.95504693 | W23: =IFERROR(MAX(W9:W16),"") -> 0.265 | X23: =IFERROR(MAX(X9:X16),"") -> 2.5067864
A25: TIER 2 – EMERGING-MARKETS TELECOM / WIRELESS (>10% Projected Organic Revenue Growth)
A26: Bharti Airtel Limited | B26: BSE:532454 | C26: 116130 | D26: 137956 | E26: 23300 | F26: 0.5 | G26: 0.38 | H26: 0.22 | I26: 0.22 | J26: =IF(OR(D26="",D26=0,E26="",E26=0),"NM",D26/E26) -> 5.9208584 | K26: =IF(OR(G26<=0,E26=0,D26=0),"NM",IF(D26/(E26*G26)>100,"NM",D26/(E26*G26))) -> 15.581206 | M26: 478 | N26: 3 | P26: 0.5 | Q26: 14000 | R26: =IFERROR(Q26/(Q26+S26+U26),"") -> 0.11070694 | S26: 0 | T26: =IFERROR(S26/(Q26+S26+U26),"") -> 0 | U26: 112460 | V26: =IFERROR(U26/(Q26+S26+U26),"") -> 0.88929306 | W26: 0.25 | X26: =IFERROR(P26/(1+(Q26/U26)*(1-W26)+S26/U26),"") -> 0.45730319
A27: MTN Group Limited | B27: JSE:MTN | C27: 21828 | D27: 24074 | E27: 10010 | F27: 0.45 | G27: 0.44 | H27: 0.19 | I27: 0.08 | J27: =IF(OR(D27="",D27=0,E27="",E27=0),"NM",D27/E27) -> 2.404995 | K27: =IF(OR(G27<=0,E27=0,D27=0),"NM",IF(D27/(E27*G27)>100,"NM",D27/(E27*G27))) -> 5.4658977 | M27: 307 | N27: 3.5 | P27: 0.97 | Q27: 8100 | R27: =IFERROR(Q27/(Q27+S27+U27),"") -> 0.29454545 | S27: 0 | T27: =IFERROR(S27/(Q27+S27+U27),"") -> 0 | U27: 19400 | V27: =IFERROR(U27/(Q27+S27+U27),"") -> 0.70545455 | W27: 0.28 | X27: =IFERROR(P27/(1+(Q27/U27)*(1-W27)+S27/U27),"") -> 0.74579899
A28: Vodacom Group Limited | B28: JSE:VOD | C28: 17080 | D28: 20380 | E28: 8860 | F28: 0.55 | G28: 0.4 | H28: 0.18 | I28: 0.12 | J28: =IF(OR(D28="",D28=0,E28="",E28=0),"NM",D28/E28) -> 2.3002257 | K28: =IF(OR(G28<=0,E28=0,D28=0),"NM",IF(D28/(E28*G28)>100,"NM",D28/(E28*G28))) -> 5.7505643 | M28: 83 | N28: 7 | P28: 0.42 | Q28: 4400 | R28: =IFERROR(Q28/(Q28+S28+U28),"") -> 0.19634092 | S28: 0 | T28: =IFERROR(S28/(Q28+S28+U28),"") -> 0 | U28: 18010 | V28: =IFERROR(U28/(Q28+S28+U28),"") -> 0.80365908 | W28: 0.28 | X28: =IFERROR(P28/(1+(Q28/U28)*(1-W28)+S28/U28),"") -> 0.35717254
A29: Vodafone Idea Limited | B29: NSEI:IDEA | C29: 15293 | D29: 36374 | E29: 4000 | F29: 0.3 | G29: 0.27 | H29: 0.25 | I29: 0.05 | J29: =IF(OR(D29="",D29=0,E29="",E29=0),"NM",D29/E29) -> 9.0935 | K29: =IF(OR(G29<=0,E29=0,D29=0),"NM",IF(D29/(E29*G29)>100,"NM",D29/(E29*G29))) -> 33.67963 | M29: 198 | N29: 2 | P29: 1.1 | Q29: 23000 | R29: =IFERROR(Q29/(Q29+S29+U29),"") -> 0.71875 | S29: 0 | T29: =IFERROR(S29/(Q29+S29+U29),"") -> 0 | U29: 9000 | V29: =IFERROR(U29/(Q29+S29+U29),"") -> 0.28125 | W29: 0.25 | X29: =IFERROR(P29/(1+(Q29/U29)*(1-W29)+S29/U29),"") -> 0.37714286
